[2024-12-03T22:54:31.232+0000] {local_task_job_runner.py:123} INFO - ::group::Pre task execution logs
[2024-12-03T22:54:31.246+0000] {taskinstance.py:2613} INFO - Dependencies all met for dep_context=non-requeueable deps ti=<TaskInstance: process_brands_batches.get_next_batch manual__2024-12-03T22:32:56.795699+00:00 [queued]>
[2024-12-03T22:54:31.252+0000] {taskinstance.py:2613} INFO - Dependencies all met for dep_context=requeueable deps ti=<TaskInstance: process_brands_batches.get_next_batch manual__2024-12-03T22:32:56.795699+00:00 [queued]>
[2024-12-03T22:54:31.253+0000] {taskinstance.py:2866} INFO - Starting attempt 4 of 4
[2024-12-03T22:54:31.264+0000] {taskinstance.py:2889} INFO - Executing <Task(PythonOperator): get_next_batch> on 2024-12-03 22:32:56.795699+00:00
[2024-12-03T22:54:31.271+0000] {warnings.py:112} WARNING - /home/***/.local/lib/python3.12/site-packages/***/task/task_runner/standard_task_runner.py:70: DeprecationWarning: This process (pid=75) is multi-threaded, use of fork() may lead to deadlocks in the child.
  pid = os.fork()

[2024-12-03T22:54:31.275+0000] {standard_task_runner.py:72} INFO - Started process 76 to run task
[2024-12-03T22:54:31.275+0000] {standard_task_runner.py:104} INFO - Running: ['***', 'tasks', 'run', 'process_brands_batches', 'get_next_batch', 'manual__2024-12-03T22:32:56.795699+00:00', '--job-id', '317', '--raw', '--subdir', 'DAGS_FOLDER/llm_test.py', '--cfg-path', '/tmp/tmplzqgrndq']
[2024-12-03T22:54:31.279+0000] {standard_task_runner.py:105} INFO - Job 317: Subtask get_next_batch
[2024-12-03T22:54:31.332+0000] {task_command.py:467} INFO - Running <TaskInstance: process_brands_batches.get_next_batch manual__2024-12-03T22:32:56.795699+00:00 [running]> on host c7846de93276
[2024-12-03T22:54:31.389+0000] {taskinstance.py:3132} INFO - Exporting env vars: AIRFLOW_CTX_DAG_OWNER='artzsh' AIRFLOW_CTX_DAG_ID='process_brands_batches' AIRFLOW_CTX_TASK_ID='get_next_batch' AIRFLOW_CTX_EXECUTION_DATE='2024-12-03T22:32:56.795699+00:00' AIRFLOW_CTX_TRY_NUMBER='4' AIRFLOW_CTX_DAG_RUN_ID='manual__2024-12-03T22:32:56.795699+00:00'
[2024-12-03T22:54:31.390+0000] {taskinstance.py:731} INFO - ::endgroup::
[2024-12-03T22:54:31.423+0000] {base.py:84} INFO - Retrieving connection 'postgres_default'
[2024-12-03T22:56:44.206+0000] {llm_test.py:75} ERROR - Ошибка при извлечении брендов: connection to server at "172.17.176.1", port 5432 failed: Connection timed out
	Is the server running on that host and accepting TCP/IP connections?

[2024-12-03T22:56:44.207+0000] {taskinstance.py:3311} ERROR - Task failed with exception
Traceback (most recent call last):
  File "/opt/airflow/dags/llm_test.py", line 45, in get_next_batch
    conn = psycopg2.connect(**postgres_conn_params)
           ^^^^^^^^^^^^^^^^^^^^^^^^^^^^^^^^^^^^^^^^
  File "/home/airflow/.local/lib/python3.12/site-packages/psycopg2/__init__.py", line 122, in connect
    conn = _connect(dsn, connection_factory=connection_factory, **kwasync)
           ^^^^^^^^^^^^^^^^^^^^^^^^^^^^^^^^^^^^^^^^^^^^^^^^^^^^^^^^^^^^^^^
psycopg2.OperationalError: connection to server at "172.17.176.1", port 5432 failed: Connection timed out
	Is the server running on that host and accepting TCP/IP connections?


During handling of the above exception, another exception occurred:

Traceback (most recent call last):
  File "/home/airflow/.local/lib/python3.12/site-packages/airflow/models/taskinstance.py", line 767, in _execute_task
    result = _execute_callable(context=context, **execute_callable_kwargs)
             ^^^^^^^^^^^^^^^^^^^^^^^^^^^^^^^^^^^^^^^^^^^^^^^^^^^^^^^^^^^^^
  File "/home/airflow/.local/lib/python3.12/site-packages/airflow/models/taskinstance.py", line 733, in _execute_callable
    return ExecutionCallableRunner(
           ^^^^^^^^^^^^^^^^^^^^^^^^
  File "/home/airflow/.local/lib/python3.12/site-packages/airflow/utils/operator_helpers.py", line 252, in run
    return self.func(*args, **kwargs)
           ^^^^^^^^^^^^^^^^^^^^^^^^^^
  File "/home/airflow/.local/lib/python3.12/site-packages/airflow/models/baseoperator.py", line 417, in wrapper
    return func(self, *args, **kwargs)
           ^^^^^^^^^^^^^^^^^^^^^^^^^^^
  File "/home/airflow/.local/lib/python3.12/site-packages/airflow/operators/python.py", line 238, in execute
    return_value = self.execute_callable()
                   ^^^^^^^^^^^^^^^^^^^^^^^
  File "/home/airflow/.local/lib/python3.12/site-packages/airflow/operators/python.py", line 256, in execute_callable
    return runner.run(*self.op_args, **self.op_kwargs)
           ^^^^^^^^^^^^^^^^^^^^^^^^^^^^^^^^^^^^^^^^^^^
  File "/home/airflow/.local/lib/python3.12/site-packages/airflow/utils/operator_helpers.py", line 252, in run
    return self.func(*args, **kwargs)
           ^^^^^^^^^^^^^^^^^^^^^^^^^^
  File "/opt/airflow/dags/llm_test.py", line 78, in get_next_batch
    if cursor:
       ^^^^^^
UnboundLocalError: cannot access local variable 'cursor' where it is not associated with a value
[2024-12-03T22:56:44.221+0000] {taskinstance.py:1225} INFO - Marking task as FAILED. dag_id=process_brands_batches, task_id=get_next_batch, run_id=manual__2024-12-03T22:32:56.795699+00:00, execution_date=20241203T223256, start_date=20241203T225431, end_date=20241203T225644
[2024-12-03T22:56:44.235+0000] {taskinstance.py:340} INFO - ::group::Post task execution logs
[2024-12-03T22:56:44.235+0000] {standard_task_runner.py:124} ERROR - Failed to execute job 317 for task get_next_batch (cannot access local variable 'cursor' where it is not associated with a value; 76)
Traceback (most recent call last):
  File "/opt/airflow/dags/llm_test.py", line 45, in get_next_batch
    conn = psycopg2.connect(**postgres_conn_params)
           ^^^^^^^^^^^^^^^^^^^^^^^^^^^^^^^^^^^^^^^^
  File "/home/airflow/.local/lib/python3.12/site-packages/psycopg2/__init__.py", line 122, in connect
    conn = _connect(dsn, connection_factory=connection_factory, **kwasync)
           ^^^^^^^^^^^^^^^^^^^^^^^^^^^^^^^^^^^^^^^^^^^^^^^^^^^^^^^^^^^^^^^
psycopg2.OperationalError: connection to server at "172.17.176.1", port 5432 failed: Connection timed out
	Is the server running on that host and accepting TCP/IP connections?


During handling of the above exception, another exception occurred:

Traceback (most recent call last):
  File "/home/airflow/.local/lib/python3.12/site-packages/airflow/task/task_runner/standard_task_runner.py", line 117, in _start_by_fork
    ret = args.func(args, dag=self.dag)
          ^^^^^^^^^^^^^^^^^^^^^^^^^^^^^
  File "/home/airflow/.local/lib/python3.12/site-packages/airflow/cli/cli_config.py", line 49, in command
    return func(*args, **kwargs)
           ^^^^^^^^^^^^^^^^^^^^^
  File "/home/airflow/.local/lib/python3.12/site-packages/airflow/utils/cli.py", line 116, in wrapper
    return f(*args, **kwargs)
           ^^^^^^^^^^^^^^^^^^
  File "/home/airflow/.local/lib/python3.12/site-packages/airflow/cli/commands/task_command.py", line 483, in task_run
    task_return_code = _run_task_by_selected_method(args, _dag, ti)
                       ^^^^^^^^^^^^^^^^^^^^^^^^^^^^^^^^^^^^^^^^^^^^
  File "/home/airflow/.local/lib/python3.12/site-packages/airflow/cli/commands/task_command.py", line 256, in _run_task_by_selected_method
    return _run_raw_task(args, ti)
           ^^^^^^^^^^^^^^^^^^^^^^^
  File "/home/airflow/.local/lib/python3.12/site-packages/airflow/cli/commands/task_command.py", line 341, in _run_raw_task
    return ti._run_raw_task(
           ^^^^^^^^^^^^^^^^^
  File "/home/airflow/.local/lib/python3.12/site-packages/airflow/utils/session.py", line 97, in wrapper
    return func(*args, session=session, **kwargs)
           ^^^^^^^^^^^^^^^^^^^^^^^^^^^^^^^^^^^^^^
  File "/home/airflow/.local/lib/python3.12/site-packages/airflow/models/taskinstance.py", line 3005, in _run_raw_task
    return _run_raw_task(
           ^^^^^^^^^^^^^^
  File "/home/airflow/.local/lib/python3.12/site-packages/airflow/models/taskinstance.py", line 273, in _run_raw_task
    TaskInstance._execute_task_with_callbacks(
  File "/home/airflow/.local/lib/python3.12/site-packages/airflow/models/taskinstance.py", line 3159, in _execute_task_with_callbacks
    result = self._execute_task(context, task_orig)
             ^^^^^^^^^^^^^^^^^^^^^^^^^^^^^^^^^^^^^^
  File "/home/airflow/.local/lib/python3.12/site-packages/airflow/models/taskinstance.py", line 3183, in _execute_task
    return _execute_task(self, context, task_orig)
           ^^^^^^^^^^^^^^^^^^^^^^^^^^^^^^^^^^^^^^^
  File "/home/airflow/.local/lib/python3.12/site-packages/airflow/models/taskinstance.py", line 767, in _execute_task
    result = _execute_callable(context=context, **execute_callable_kwargs)
             ^^^^^^^^^^^^^^^^^^^^^^^^^^^^^^^^^^^^^^^^^^^^^^^^^^^^^^^^^^^^^
  File "/home/airflow/.local/lib/python3.12/site-packages/airflow/models/taskinstance.py", line 733, in _execute_callable
    return ExecutionCallableRunner(
           ^^^^^^^^^^^^^^^^^^^^^^^^
  File "/home/airflow/.local/lib/python3.12/site-packages/airflow/utils/operator_helpers.py", line 252, in run
    return self.func(*args, **kwargs)
           ^^^^^^^^^^^^^^^^^^^^^^^^^^
  File "/home/airflow/.local/lib/python3.12/site-packages/airflow/models/baseoperator.py", line 417, in wrapper
    return func(self, *args, **kwargs)
           ^^^^^^^^^^^^^^^^^^^^^^^^^^^
  File "/home/airflow/.local/lib/python3.12/site-packages/airflow/operators/python.py", line 238, in execute
    return_value = self.execute_callable()
                   ^^^^^^^^^^^^^^^^^^^^^^^
  File "/home/airflow/.local/lib/python3.12/site-packages/airflow/operators/python.py", line 256, in execute_callable
    return runner.run(*self.op_args, **self.op_kwargs)
           ^^^^^^^^^^^^^^^^^^^^^^^^^^^^^^^^^^^^^^^^^^^
  File "/home/airflow/.local/lib/python3.12/site-packages/airflow/utils/operator_helpers.py", line 252, in run
    return self.func(*args, **kwargs)
           ^^^^^^^^^^^^^^^^^^^^^^^^^^
  File "/opt/airflow/dags/llm_test.py", line 78, in get_next_batch
    if cursor:
       ^^^^^^
UnboundLocalError: cannot access local variable 'cursor' where it is not associated with a value
[2024-12-03T22:56:44.272+0000] {local_task_job_runner.py:266} INFO - Task exited with return code 1
[2024-12-03T22:56:44.286+0000] {taskinstance.py:3895} INFO - 0 downstream tasks scheduled from follow-on schedule check
[2024-12-03T22:56:44.290+0000] {local_task_job_runner.py:245} INFO - ::endgroup::
