[2024-12-06T14:53:19.757+0000] {local_task_job_runner.py:123} INFO - ::group::Pre task execution logs
[2024-12-06T14:53:19.768+0000] {taskinstance.py:2613} INFO - Dependencies all met for dep_context=non-requeueable deps ti=<TaskInstance: insert_cleaned_data.insert_cleaned_data manual__2024-12-06T14:53:18.041571+00:00 [queued]>
[2024-12-06T14:53:19.774+0000] {taskinstance.py:2613} INFO - Dependencies all met for dep_context=requeueable deps ti=<TaskInstance: insert_cleaned_data.insert_cleaned_data manual__2024-12-06T14:53:18.041571+00:00 [queued]>
[2024-12-06T14:53:19.774+0000] {taskinstance.py:2866} INFO - Starting attempt 1 of 4
[2024-12-06T14:53:19.784+0000] {taskinstance.py:2889} INFO - Executing <Task(PythonOperator): insert_cleaned_data> on 2024-12-06 14:53:18.041571+00:00
[2024-12-06T14:53:19.788+0000] {warnings.py:112} WARNING - /home/***/.local/lib/python3.12/site-packages/***/task/task_runner/standard_task_runner.py:70: DeprecationWarning: This process (pid=2437) is multi-threaded, use of fork() may lead to deadlocks in the child.
  pid = os.fork()

[2024-12-06T14:53:19.789+0000] {standard_task_runner.py:72} INFO - Started process 2438 to run task
[2024-12-06T14:53:19.790+0000] {standard_task_runner.py:104} INFO - Running: ['***', 'tasks', 'run', 'insert_cleaned_data', 'insert_cleaned_data', 'manual__2024-12-06T14:53:18.041571+00:00', '--job-id', '1992', '--raw', '--subdir', 'DAGS_FOLDER/insert_cleaned_data.py', '--cfg-path', '/tmp/tmpo0kyq0j9']
[2024-12-06T14:53:19.790+0000] {standard_task_runner.py:105} INFO - Job 1992: Subtask insert_cleaned_data
[2024-12-06T14:53:19.819+0000] {task_command.py:467} INFO - Running <TaskInstance: insert_cleaned_data.insert_cleaned_data manual__2024-12-06T14:53:18.041571+00:00 [running]> on host cb0074367deb
[2024-12-06T14:53:19.868+0000] {taskinstance.py:3132} INFO - Exporting env vars: AIRFLOW_CTX_DAG_OWNER='artzsh' AIRFLOW_CTX_DAG_ID='insert_cleaned_data' AIRFLOW_CTX_TASK_ID='insert_cleaned_data' AIRFLOW_CTX_EXECUTION_DATE='2024-12-06T14:53:18.041571+00:00' AIRFLOW_CTX_TRY_NUMBER='1' AIRFLOW_CTX_DAG_RUN_ID='manual__2024-12-06T14:53:18.041571+00:00'
[2024-12-06T14:53:19.868+0000] {taskinstance.py:731} INFO - ::endgroup::
[2024-12-06T14:53:19.887+0000] {insert_cleaned_data.py:51} INFO - Обрабатываем ключ: 1
[2024-12-06T14:53:19.888+0000] {insert_cleaned_data.py:67} INFO - Источник данных: DDS-STG.eCommerce_Oct
[2024-12-06T14:53:19.888+0000] {insert_cleaned_data.py:68} INFO - Целевая таблица: DDS.final_table
[2024-12-06T14:53:19.893+0000] {base.py:84} INFO - Retrieving connection 'database_cloud'
[2024-12-06T14:53:19.955+0000] {insert_cleaned_data.py:89} INFO - Соединение с PostgreSQL установлено.
[2024-12-06T14:53:43.436+0000] {insert_cleaned_data.py:165} INFO - Вставлено записей: 100000. Всего вставлено: 100000.
[2024-12-06T14:54:09.678+0000] {insert_cleaned_data.py:165} INFO - Вставлено записей: 100000. Всего вставлено: 200000.
[2024-12-06T14:54:34.413+0000] {insert_cleaned_data.py:165} INFO - Вставлено записей: 100000. Всего вставлено: 300000.
[2024-12-06T14:55:01.448+0000] {insert_cleaned_data.py:165} INFO - Вставлено записей: 100000. Всего вставлено: 400000.
[2024-12-06T14:55:27.586+0000] {insert_cleaned_data.py:165} INFO - Вставлено записей: 100000. Всего вставлено: 500000.
[2024-12-06T14:55:54.328+0000] {insert_cleaned_data.py:165} INFO - Вставлено записей: 100000. Всего вставлено: 600000.
[2024-12-06T14:56:20.258+0000] {insert_cleaned_data.py:165} INFO - Вставлено записей: 100000. Всего вставлено: 700000.
[2024-12-06T14:56:45.123+0000] {insert_cleaned_data.py:165} INFO - Вставлено записей: 100000. Всего вставлено: 800000.
[2024-12-06T14:57:11.194+0000] {insert_cleaned_data.py:165} INFO - Вставлено записей: 100000. Всего вставлено: 900000.
[2024-12-06T14:58:37.436+0000] {insert_cleaned_data.py:165} INFO - Вставлено записей: 100000. Всего вставлено: 1000000.
[2024-12-06T14:59:54.048+0000] {insert_cleaned_data.py:165} INFO - Вставлено записей: 100000. Всего вставлено: 1100000.
[2024-12-06T15:01:23.462+0000] {insert_cleaned_data.py:165} INFO - Вставлено записей: 100000. Всего вставлено: 1200000.
[2024-12-06T15:02:50.333+0000] {insert_cleaned_data.py:165} INFO - Вставлено записей: 100000. Всего вставлено: 1300000.
[2024-12-06T15:04:18.228+0000] {insert_cleaned_data.py:165} INFO - Вставлено записей: 100000. Всего вставлено: 1400000.
[2024-12-06T15:05:47.438+0000] {insert_cleaned_data.py:165} INFO - Вставлено записей: 100000. Всего вставлено: 1500000.
[2024-12-06T15:07:13.788+0000] {insert_cleaned_data.py:165} INFO - Вставлено записей: 100000. Всего вставлено: 1600000.
[2024-12-06T15:08:38.055+0000] {insert_cleaned_data.py:165} INFO - Вставлено записей: 100000. Всего вставлено: 1700000.
[2024-12-06T15:09:37.766+0000] {local_task_job_runner.py:346} WARNING - State of this instance has been externally set to failed. Terminating instance.
[2024-12-06T15:09:37.767+0000] {local_task_job_runner.py:245} INFO - ::endgroup::
[2024-12-06T15:09:37.768+0000] {process_utils.py:132} INFO - Sending 15 to group 2438. PIDs of all processes in the group: [2438]
[2024-12-06T15:09:37.768+0000] {process_utils.py:87} INFO - Sending the signal 15 to group 2438
[2024-12-06T15:10:02.241+0000] {taskinstance.py:3093} ERROR - Received SIGTERM. Terminating subprocesses.
[2024-12-06T15:10:02.242+0000] {insert_cleaned_data.py:173} ERROR - Ошибка при вставке данных: SSL SYSCALL error: EOF detected

[2024-12-06T15:10:02.243+0000] {insert_cleaned_data.py:180} INFO - Курсор закрыт.
[2024-12-06T15:10:02.245+0000] {insert_cleaned_data.py:183} INFO - Соединение с PostgreSQL закрыто.
[2024-12-06T15:10:02.246+0000] {taskinstance.py:3311} ERROR - Task failed with exception
Traceback (most recent call last):
  File "/opt/airflow/dags/insert_cleaned_data.py", line 126, in insert_cleaned_data
    cursor.execute(select_query)
psycopg2.OperationalError: SSL SYSCALL error: EOF detected


During handling of the above exception, another exception occurred:

Traceback (most recent call last):
  File "/home/airflow/.local/lib/python3.12/site-packages/airflow/models/taskinstance.py", line 767, in _execute_task
    result = _execute_callable(context=context, **execute_callable_kwargs)
             ^^^^^^^^^^^^^^^^^^^^^^^^^^^^^^^^^^^^^^^^^^^^^^^^^^^^^^^^^^^^^
  File "/home/airflow/.local/lib/python3.12/site-packages/airflow/models/taskinstance.py", line 733, in _execute_callable
    return ExecutionCallableRunner(
           ^^^^^^^^^^^^^^^^^^^^^^^^
  File "/home/airflow/.local/lib/python3.12/site-packages/airflow/utils/operator_helpers.py", line 252, in run
    return self.func(*args, **kwargs)
           ^^^^^^^^^^^^^^^^^^^^^^^^^^
  File "/home/airflow/.local/lib/python3.12/site-packages/airflow/models/baseoperator.py", line 417, in wrapper
    return func(self, *args, **kwargs)
           ^^^^^^^^^^^^^^^^^^^^^^^^^^^
  File "/home/airflow/.local/lib/python3.12/site-packages/airflow/operators/python.py", line 238, in execute
    return_value = self.execute_callable()
                   ^^^^^^^^^^^^^^^^^^^^^^^
  File "/home/airflow/.local/lib/python3.12/site-packages/airflow/operators/python.py", line 256, in execute_callable
    return runner.run(*self.op_args, **self.op_kwargs)
           ^^^^^^^^^^^^^^^^^^^^^^^^^^^^^^^^^^^^^^^^^^^
  File "/home/airflow/.local/lib/python3.12/site-packages/airflow/utils/operator_helpers.py", line 252, in run
    return self.func(*args, **kwargs)
           ^^^^^^^^^^^^^^^^^^^^^^^^^^
  File "/opt/airflow/dags/insert_cleaned_data.py", line 175, in insert_cleaned_data
    conn.rollback()
psycopg2.InterfaceError: connection already closed
[2024-12-06T15:10:02.262+0000] {taskinstance.py:1225} INFO - Marking task as UP_FOR_RETRY. dag_id=insert_cleaned_data, task_id=insert_cleaned_data, run_id=manual__2024-12-06T14:53:18.041571+00:00, execution_date=20241206T145318, start_date=20241206T145319, end_date=20241206T151002
[2024-12-06T15:10:02.280+0000] {taskinstance.py:340} INFO - ::group::Post task execution logs
[2024-12-06T15:10:02.281+0000] {standard_task_runner.py:124} ERROR - Failed to execute job 1992 for task insert_cleaned_data (connection already closed; 2438)
Traceback (most recent call last):
  File "/opt/airflow/dags/insert_cleaned_data.py", line 126, in insert_cleaned_data
    cursor.execute(select_query)
psycopg2.OperationalError: SSL SYSCALL error: EOF detected


During handling of the above exception, another exception occurred:

Traceback (most recent call last):
  File "/home/airflow/.local/lib/python3.12/site-packages/airflow/task/task_runner/standard_task_runner.py", line 117, in _start_by_fork
    ret = args.func(args, dag=self.dag)
          ^^^^^^^^^^^^^^^^^^^^^^^^^^^^^
  File "/home/airflow/.local/lib/python3.12/site-packages/airflow/cli/cli_config.py", line 49, in command
    return func(*args, **kwargs)
           ^^^^^^^^^^^^^^^^^^^^^
  File "/home/airflow/.local/lib/python3.12/site-packages/airflow/utils/cli.py", line 116, in wrapper
    return f(*args, **kwargs)
           ^^^^^^^^^^^^^^^^^^
  File "/home/airflow/.local/lib/python3.12/site-packages/airflow/cli/commands/task_command.py", line 483, in task_run
    task_return_code = _run_task_by_selected_method(args, _dag, ti)
                       ^^^^^^^^^^^^^^^^^^^^^^^^^^^^^^^^^^^^^^^^^^^^
  File "/home/airflow/.local/lib/python3.12/site-packages/airflow/cli/commands/task_command.py", line 256, in _run_task_by_selected_method
    return _run_raw_task(args, ti)
           ^^^^^^^^^^^^^^^^^^^^^^^
  File "/home/airflow/.local/lib/python3.12/site-packages/airflow/cli/commands/task_command.py", line 341, in _run_raw_task
    return ti._run_raw_task(
           ^^^^^^^^^^^^^^^^^
  File "/home/airflow/.local/lib/python3.12/site-packages/airflow/utils/session.py", line 97, in wrapper
    return func(*args, session=session, **kwargs)
           ^^^^^^^^^^^^^^^^^^^^^^^^^^^^^^^^^^^^^^
  File "/home/airflow/.local/lib/python3.12/site-packages/airflow/models/taskinstance.py", line 3005, in _run_raw_task
    return _run_raw_task(
           ^^^^^^^^^^^^^^
  File "/home/airflow/.local/lib/python3.12/site-packages/airflow/models/taskinstance.py", line 273, in _run_raw_task
    TaskInstance._execute_task_with_callbacks(
  File "/home/airflow/.local/lib/python3.12/site-packages/airflow/models/taskinstance.py", line 3159, in _execute_task_with_callbacks
    result = self._execute_task(context, task_orig)
             ^^^^^^^^^^^^^^^^^^^^^^^^^^^^^^^^^^^^^^
  File "/home/airflow/.local/lib/python3.12/site-packages/airflow/models/taskinstance.py", line 3183, in _execute_task
    return _execute_task(self, context, task_orig)
           ^^^^^^^^^^^^^^^^^^^^^^^^^^^^^^^^^^^^^^^
  File "/home/airflow/.local/lib/python3.12/site-packages/airflow/models/taskinstance.py", line 767, in _execute_task
    result = _execute_callable(context=context, **execute_callable_kwargs)
             ^^^^^^^^^^^^^^^^^^^^^^^^^^^^^^^^^^^^^^^^^^^^^^^^^^^^^^^^^^^^^
  File "/home/airflow/.local/lib/python3.12/site-packages/airflow/models/taskinstance.py", line 733, in _execute_callable
    return ExecutionCallableRunner(
           ^^^^^^^^^^^^^^^^^^^^^^^^
  File "/home/airflow/.local/lib/python3.12/site-packages/airflow/utils/operator_helpers.py", line 252, in run
    return self.func(*args, **kwargs)
           ^^^^^^^^^^^^^^^^^^^^^^^^^^
  File "/home/airflow/.local/lib/python3.12/site-packages/airflow/models/baseoperator.py", line 417, in wrapper
    return func(self, *args, **kwargs)
           ^^^^^^^^^^^^^^^^^^^^^^^^^^^
  File "/home/airflow/.local/lib/python3.12/site-packages/airflow/operators/python.py", line 238, in execute
    return_value = self.execute_callable()
                   ^^^^^^^^^^^^^^^^^^^^^^^
  File "/home/airflow/.local/lib/python3.12/site-packages/airflow/operators/python.py", line 256, in execute_callable
    return runner.run(*self.op_args, **self.op_kwargs)
           ^^^^^^^^^^^^^^^^^^^^^^^^^^^^^^^^^^^^^^^^^^^
  File "/home/airflow/.local/lib/python3.12/site-packages/airflow/utils/operator_helpers.py", line 252, in run
    return self.func(*args, **kwargs)
           ^^^^^^^^^^^^^^^^^^^^^^^^^^
  File "/opt/airflow/dags/insert_cleaned_data.py", line 175, in insert_cleaned_data
    conn.rollback()
psycopg2.InterfaceError: connection already closed
[2024-12-06T15:10:02.338+0000] {process_utils.py:80} INFO - Process psutil.Process(pid=2438, status='terminated', exitcode=1, started='14:53:19') (2438) terminated with exit code 1
