[2024-12-05T20:43:33.931+0000] {local_task_job_runner.py:123} INFO - ::group::Pre task execution logs
[2024-12-05T20:43:33.945+0000] {taskinstance.py:2613} INFO - Dependencies all met for dep_context=non-requeueable deps ti=<TaskInstance: brand_category_mapping.get_next_batch manual__2024-12-05T20:43:32.589341+00:00 [queued]>
[2024-12-05T20:43:33.951+0000] {taskinstance.py:2613} INFO - Dependencies all met for dep_context=requeueable deps ti=<TaskInstance: brand_category_mapping.get_next_batch manual__2024-12-05T20:43:32.589341+00:00 [queued]>
[2024-12-05T20:43:33.952+0000] {taskinstance.py:2866} INFO - Starting attempt 1 of 4
[2024-12-05T20:43:33.964+0000] {taskinstance.py:2889} INFO - Executing <Task(PythonOperator): get_next_batch> on 2024-12-05 20:43:32.589341+00:00
[2024-12-05T20:43:33.970+0000] {warnings.py:112} WARNING - /home/***/.local/lib/python3.12/site-packages/***/task/task_runner/standard_task_runner.py:70: DeprecationWarning: This process (pid=2282) is multi-threaded, use of fork() may lead to deadlocks in the child.
  pid = os.fork()

[2024-12-05T20:43:33.972+0000] {standard_task_runner.py:72} INFO - Started process 2286 to run task
[2024-12-05T20:43:33.972+0000] {standard_task_runner.py:104} INFO - Running: ['***', 'tasks', 'run', 'brand_category_mapping', 'get_next_batch', 'manual__2024-12-05T20:43:32.589341+00:00', '--job-id', '535', '--raw', '--subdir', 'DAGS_FOLDER/llm_mapping.py', '--cfg-path', '/tmp/tmpfv8m3thh']
[2024-12-05T20:43:33.974+0000] {standard_task_runner.py:105} INFO - Job 535: Subtask get_next_batch
[2024-12-05T20:43:34.020+0000] {task_command.py:467} INFO - Running <TaskInstance: brand_category_mapping.get_next_batch manual__2024-12-05T20:43:32.589341+00:00 [running]> on host c7780884450d
[2024-12-05T20:43:34.081+0000] {taskinstance.py:3132} INFO - Exporting env vars: AIRFLOW_CTX_DAG_OWNER='artzsh' AIRFLOW_CTX_DAG_ID='brand_category_mapping' AIRFLOW_CTX_TASK_ID='get_next_batch' AIRFLOW_CTX_EXECUTION_DATE='2024-12-05T20:43:32.589341+00:00' AIRFLOW_CTX_TRY_NUMBER='1' AIRFLOW_CTX_DAG_RUN_ID='manual__2024-12-05T20:43:32.589341+00:00'
[2024-12-05T20:43:34.082+0000] {taskinstance.py:731} INFO - ::endgroup::
[2024-12-05T20:43:34.107+0000] {base.py:84} INFO - Retrieving connection 'database_cloud'
[2024-12-05T20:43:35.004+0000] {llm_mapping.py:76} ERROR - Ошибка при извлечении брендов: relation "dds.unique_brands" does not exist
LINE 1: SELECT brand FROM DDS.unique_brands ORDER BY brand LIMIT 25 ...
                          ^

[2024-12-05T20:43:35.005+0000] {taskinstance.py:3311} ERROR - Task failed with exception
Traceback (most recent call last):
  File "/home/airflow/.local/lib/python3.12/site-packages/airflow/models/taskinstance.py", line 767, in _execute_task
    result = _execute_callable(context=context, **execute_callable_kwargs)
             ^^^^^^^^^^^^^^^^^^^^^^^^^^^^^^^^^^^^^^^^^^^^^^^^^^^^^^^^^^^^^
  File "/home/airflow/.local/lib/python3.12/site-packages/airflow/models/taskinstance.py", line 733, in _execute_callable
    return ExecutionCallableRunner(
           ^^^^^^^^^^^^^^^^^^^^^^^^
  File "/home/airflow/.local/lib/python3.12/site-packages/airflow/utils/operator_helpers.py", line 252, in run
    return self.func(*args, **kwargs)
           ^^^^^^^^^^^^^^^^^^^^^^^^^^
  File "/home/airflow/.local/lib/python3.12/site-packages/airflow/models/baseoperator.py", line 417, in wrapper
    return func(self, *args, **kwargs)
           ^^^^^^^^^^^^^^^^^^^^^^^^^^^
  File "/home/airflow/.local/lib/python3.12/site-packages/airflow/operators/python.py", line 238, in execute
    return_value = self.execute_callable()
                   ^^^^^^^^^^^^^^^^^^^^^^^
  File "/home/airflow/.local/lib/python3.12/site-packages/airflow/operators/python.py", line 256, in execute_callable
    return runner.run(*self.op_args, **self.op_kwargs)
           ^^^^^^^^^^^^^^^^^^^^^^^^^^^^^^^^^^^^^^^^^^^
  File "/home/airflow/.local/lib/python3.12/site-packages/airflow/utils/operator_helpers.py", line 252, in run
    return self.func(*args, **kwargs)
           ^^^^^^^^^^^^^^^^^^^^^^^^^^
  File "/opt/airflow/dags/llm_mapping.py", line 54, in get_next_batch
    cursor.execute(query)
psycopg2.errors.UndefinedTable: relation "dds.unique_brands" does not exist
LINE 1: SELECT brand FROM DDS.unique_brands ORDER BY brand LIMIT 25 ...
                          ^

[2024-12-05T20:43:35.019+0000] {taskinstance.py:1225} INFO - Marking task as UP_FOR_RETRY. dag_id=brand_category_mapping, task_id=get_next_batch, run_id=manual__2024-12-05T20:43:32.589341+00:00, execution_date=20241205T204332, start_date=20241205T204333, end_date=20241205T204335
[2024-12-05T20:43:35.038+0000] {taskinstance.py:340} INFO - ::group::Post task execution logs
[2024-12-05T20:43:35.039+0000] {standard_task_runner.py:124} ERROR - Failed to execute job 535 for task get_next_batch (relation "dds.unique_brands" does not exist
LINE 1: SELECT brand FROM DDS.unique_brands ORDER BY brand LIMIT 25 ...
                          ^
; 2286)
Traceback (most recent call last):
  File "/home/airflow/.local/lib/python3.12/site-packages/airflow/task/task_runner/standard_task_runner.py", line 117, in _start_by_fork
    ret = args.func(args, dag=self.dag)
          ^^^^^^^^^^^^^^^^^^^^^^^^^^^^^
  File "/home/airflow/.local/lib/python3.12/site-packages/airflow/cli/cli_config.py", line 49, in command
    return func(*args, **kwargs)
           ^^^^^^^^^^^^^^^^^^^^^
  File "/home/airflow/.local/lib/python3.12/site-packages/airflow/utils/cli.py", line 116, in wrapper
    return f(*args, **kwargs)
           ^^^^^^^^^^^^^^^^^^
  File "/home/airflow/.local/lib/python3.12/site-packages/airflow/cli/commands/task_command.py", line 483, in task_run
    task_return_code = _run_task_by_selected_method(args, _dag, ti)
                       ^^^^^^^^^^^^^^^^^^^^^^^^^^^^^^^^^^^^^^^^^^^^
  File "/home/airflow/.local/lib/python3.12/site-packages/airflow/cli/commands/task_command.py", line 256, in _run_task_by_selected_method
    return _run_raw_task(args, ti)
           ^^^^^^^^^^^^^^^^^^^^^^^
  File "/home/airflow/.local/lib/python3.12/site-packages/airflow/cli/commands/task_command.py", line 341, in _run_raw_task
    return ti._run_raw_task(
           ^^^^^^^^^^^^^^^^^
  File "/home/airflow/.local/lib/python3.12/site-packages/airflow/utils/session.py", line 97, in wrapper
    return func(*args, session=session, **kwargs)
           ^^^^^^^^^^^^^^^^^^^^^^^^^^^^^^^^^^^^^^
  File "/home/airflow/.local/lib/python3.12/site-packages/airflow/models/taskinstance.py", line 3005, in _run_raw_task
    return _run_raw_task(
           ^^^^^^^^^^^^^^
  File "/home/airflow/.local/lib/python3.12/site-packages/airflow/models/taskinstance.py", line 273, in _run_raw_task
    TaskInstance._execute_task_with_callbacks(
  File "/home/airflow/.local/lib/python3.12/site-packages/airflow/models/taskinstance.py", line 3159, in _execute_task_with_callbacks
    result = self._execute_task(context, task_orig)
             ^^^^^^^^^^^^^^^^^^^^^^^^^^^^^^^^^^^^^^
  File "/home/airflow/.local/lib/python3.12/site-packages/airflow/models/taskinstance.py", line 3183, in _execute_task
    return _execute_task(self, context, task_orig)
           ^^^^^^^^^^^^^^^^^^^^^^^^^^^^^^^^^^^^^^^
  File "/home/airflow/.local/lib/python3.12/site-packages/airflow/models/taskinstance.py", line 767, in _execute_task
    result = _execute_callable(context=context, **execute_callable_kwargs)
             ^^^^^^^^^^^^^^^^^^^^^^^^^^^^^^^^^^^^^^^^^^^^^^^^^^^^^^^^^^^^^
  File "/home/airflow/.local/lib/python3.12/site-packages/airflow/models/taskinstance.py", line 733, in _execute_callable
    return ExecutionCallableRunner(
           ^^^^^^^^^^^^^^^^^^^^^^^^
  File "/home/airflow/.local/lib/python3.12/site-packages/airflow/utils/operator_helpers.py", line 252, in run
    return self.func(*args, **kwargs)
           ^^^^^^^^^^^^^^^^^^^^^^^^^^
  File "/home/airflow/.local/lib/python3.12/site-packages/airflow/models/baseoperator.py", line 417, in wrapper
    return func(self, *args, **kwargs)
           ^^^^^^^^^^^^^^^^^^^^^^^^^^^
  File "/home/airflow/.local/lib/python3.12/site-packages/airflow/operators/python.py", line 238, in execute
    return_value = self.execute_callable()
                   ^^^^^^^^^^^^^^^^^^^^^^^
  File "/home/airflow/.local/lib/python3.12/site-packages/airflow/operators/python.py", line 256, in execute_callable
    return runner.run(*self.op_args, **self.op_kwargs)
           ^^^^^^^^^^^^^^^^^^^^^^^^^^^^^^^^^^^^^^^^^^^
  File "/home/airflow/.local/lib/python3.12/site-packages/airflow/utils/operator_helpers.py", line 252, in run
    return self.func(*args, **kwargs)
           ^^^^^^^^^^^^^^^^^^^^^^^^^^
  File "/opt/airflow/dags/llm_mapping.py", line 54, in get_next_batch
    cursor.execute(query)
psycopg2.errors.UndefinedTable: relation "dds.unique_brands" does not exist
LINE 1: SELECT brand FROM DDS.unique_brands ORDER BY brand LIMIT 25 ...
                          ^

[2024-12-05T20:43:35.069+0000] {local_task_job_runner.py:266} INFO - Task exited with return code 1
[2024-12-05T20:43:35.090+0000] {taskinstance.py:3895} INFO - 0 downstream tasks scheduled from follow-on schedule check
[2024-12-05T20:43:35.095+0000] {local_task_job_runner.py:245} INFO - ::endgroup::
