[2024-12-03T21:48:20.241+0000] {local_task_job_runner.py:123} INFO - ::group::Pre task execution logs
[2024-12-03T21:48:20.254+0000] {taskinstance.py:2613} INFO - Dependencies all met for dep_context=non-requeueable deps ti=<TaskInstance: process_brands_batches.get_next_batch manual__2024-12-03T21:43:17.944130+00:00 [queued]>
[2024-12-03T21:48:20.261+0000] {taskinstance.py:2613} INFO - Dependencies all met for dep_context=requeueable deps ti=<TaskInstance: process_brands_batches.get_next_batch manual__2024-12-03T21:43:17.944130+00:00 [queued]>
[2024-12-03T21:48:20.262+0000] {taskinstance.py:2866} INFO - Starting attempt 2 of 4
[2024-12-03T21:48:20.274+0000] {taskinstance.py:2889} INFO - Executing <Task(PythonOperator): get_next_batch> on 2024-12-03 21:43:17.944130+00:00
[2024-12-03T21:48:20.280+0000] {warnings.py:112} WARNING - /home/***/.local/lib/python3.12/site-packages/***/task/task_runner/standard_task_runner.py:70: DeprecationWarning: This process (pid=315) is multi-threaded, use of fork() may lead to deadlocks in the child.
  pid = os.fork()

[2024-12-03T21:48:20.281+0000] {standard_task_runner.py:72} INFO - Started process 317 to run task
[2024-12-03T21:48:20.282+0000] {standard_task_runner.py:104} INFO - Running: ['***', 'tasks', 'run', 'process_brands_batches', 'get_next_batch', 'manual__2024-12-03T21:43:17.944130+00:00', '--job-id', '300', '--raw', '--subdir', 'DAGS_FOLDER/llm_test.py', '--cfg-path', '/tmp/tmp4y0dsx17']
[2024-12-03T21:48:20.283+0000] {standard_task_runner.py:105} INFO - Job 300: Subtask get_next_batch
[2024-12-03T21:48:20.314+0000] {task_command.py:467} INFO - Running <TaskInstance: process_brands_batches.get_next_batch manual__2024-12-03T21:43:17.944130+00:00 [running]> on host 4f76d714c801
[2024-12-03T21:48:20.367+0000] {taskinstance.py:3132} INFO - Exporting env vars: AIRFLOW_CTX_DAG_OWNER='artzsh' AIRFLOW_CTX_DAG_ID='process_brands_batches' AIRFLOW_CTX_TASK_ID='get_next_batch' AIRFLOW_CTX_EXECUTION_DATE='2024-12-03T21:43:17.944130+00:00' AIRFLOW_CTX_TRY_NUMBER='2' AIRFLOW_CTX_DAG_RUN_ID='manual__2024-12-03T21:43:17.944130+00:00'
[2024-12-03T21:48:20.368+0000] {taskinstance.py:731} INFO - ::endgroup::
[2024-12-03T21:48:20.390+0000] {base.py:84} INFO - Retrieving connection 'postgres_default'
[2024-12-03T21:48:20.425+0000] {llm_test.py:72} ERROR - Ошибка при извлечении брендов: 'utf-8' codec can't decode byte 0xc2 in position 58: invalid continuation byte
[2024-12-03T21:48:20.426+0000] {taskinstance.py:3311} ERROR - Task failed with exception
Traceback (most recent call last):
  File "/opt/airflow/dags/llm_test.py", line 51, in get_next_batch
    conn = psycopg2.connect(**postgres_conn_params)
           ^^^^^^^^^^^^^^^^^^^^^^^^^^^^^^^^^^^^^^^^
  File "/home/airflow/.local/lib/python3.12/site-packages/psycopg2/__init__.py", line 122, in connect
    conn = _connect(dsn, connection_factory=connection_factory, **kwasync)
           ^^^^^^^^^^^^^^^^^^^^^^^^^^^^^^^^^^^^^^^^^^^^^^^^^^^^^^^^^^^^^^^
UnicodeDecodeError: 'utf-8' codec can't decode byte 0xc2 in position 58: invalid continuation byte

During handling of the above exception, another exception occurred:

Traceback (most recent call last):
  File "/home/airflow/.local/lib/python3.12/site-packages/airflow/models/taskinstance.py", line 767, in _execute_task
    result = _execute_callable(context=context, **execute_callable_kwargs)
             ^^^^^^^^^^^^^^^^^^^^^^^^^^^^^^^^^^^^^^^^^^^^^^^^^^^^^^^^^^^^^
  File "/home/airflow/.local/lib/python3.12/site-packages/airflow/models/taskinstance.py", line 733, in _execute_callable
    return ExecutionCallableRunner(
           ^^^^^^^^^^^^^^^^^^^^^^^^
  File "/home/airflow/.local/lib/python3.12/site-packages/airflow/utils/operator_helpers.py", line 252, in run
    return self.func(*args, **kwargs)
           ^^^^^^^^^^^^^^^^^^^^^^^^^^
  File "/home/airflow/.local/lib/python3.12/site-packages/airflow/models/baseoperator.py", line 417, in wrapper
    return func(self, *args, **kwargs)
           ^^^^^^^^^^^^^^^^^^^^^^^^^^^
  File "/home/airflow/.local/lib/python3.12/site-packages/airflow/operators/python.py", line 238, in execute
    return_value = self.execute_callable()
                   ^^^^^^^^^^^^^^^^^^^^^^^
  File "/home/airflow/.local/lib/python3.12/site-packages/airflow/operators/python.py", line 256, in execute_callable
    return runner.run(*self.op_args, **self.op_kwargs)
           ^^^^^^^^^^^^^^^^^^^^^^^^^^^^^^^^^^^^^^^^^^^
  File "/home/airflow/.local/lib/python3.12/site-packages/airflow/utils/operator_helpers.py", line 252, in run
    return self.func(*args, **kwargs)
           ^^^^^^^^^^^^^^^^^^^^^^^^^^
  File "/opt/airflow/dags/llm_test.py", line 75, in get_next_batch
    if cursor:
       ^^^^^^
UnboundLocalError: cannot access local variable 'cursor' where it is not associated with a value
[2024-12-03T21:48:20.437+0000] {taskinstance.py:1225} INFO - Marking task as UP_FOR_RETRY. dag_id=process_brands_batches, task_id=get_next_batch, run_id=manual__2024-12-03T21:43:17.944130+00:00, execution_date=20241203T214317, start_date=20241203T214820, end_date=20241203T214820
[2024-12-03T21:48:20.450+0000] {taskinstance.py:340} INFO - ::group::Post task execution logs
[2024-12-03T21:48:20.450+0000] {standard_task_runner.py:124} ERROR - Failed to execute job 300 for task get_next_batch (cannot access local variable 'cursor' where it is not associated with a value; 317)
Traceback (most recent call last):
  File "/opt/airflow/dags/llm_test.py", line 51, in get_next_batch
    conn = psycopg2.connect(**postgres_conn_params)
           ^^^^^^^^^^^^^^^^^^^^^^^^^^^^^^^^^^^^^^^^
  File "/home/airflow/.local/lib/python3.12/site-packages/psycopg2/__init__.py", line 122, in connect
    conn = _connect(dsn, connection_factory=connection_factory, **kwasync)
           ^^^^^^^^^^^^^^^^^^^^^^^^^^^^^^^^^^^^^^^^^^^^^^^^^^^^^^^^^^^^^^^
UnicodeDecodeError: 'utf-8' codec can't decode byte 0xc2 in position 58: invalid continuation byte

During handling of the above exception, another exception occurred:

Traceback (most recent call last):
  File "/home/airflow/.local/lib/python3.12/site-packages/airflow/task/task_runner/standard_task_runner.py", line 117, in _start_by_fork
    ret = args.func(args, dag=self.dag)
          ^^^^^^^^^^^^^^^^^^^^^^^^^^^^^
  File "/home/airflow/.local/lib/python3.12/site-packages/airflow/cli/cli_config.py", line 49, in command
    return func(*args, **kwargs)
           ^^^^^^^^^^^^^^^^^^^^^
  File "/home/airflow/.local/lib/python3.12/site-packages/airflow/utils/cli.py", line 116, in wrapper
    return f(*args, **kwargs)
           ^^^^^^^^^^^^^^^^^^
  File "/home/airflow/.local/lib/python3.12/site-packages/airflow/cli/commands/task_command.py", line 483, in task_run
    task_return_code = _run_task_by_selected_method(args, _dag, ti)
                       ^^^^^^^^^^^^^^^^^^^^^^^^^^^^^^^^^^^^^^^^^^^^
  File "/home/airflow/.local/lib/python3.12/site-packages/airflow/cli/commands/task_command.py", line 256, in _run_task_by_selected_method
    return _run_raw_task(args, ti)
           ^^^^^^^^^^^^^^^^^^^^^^^
  File "/home/airflow/.local/lib/python3.12/site-packages/airflow/cli/commands/task_command.py", line 341, in _run_raw_task
    return ti._run_raw_task(
           ^^^^^^^^^^^^^^^^^
  File "/home/airflow/.local/lib/python3.12/site-packages/airflow/utils/session.py", line 97, in wrapper
    return func(*args, session=session, **kwargs)
           ^^^^^^^^^^^^^^^^^^^^^^^^^^^^^^^^^^^^^^
  File "/home/airflow/.local/lib/python3.12/site-packages/airflow/models/taskinstance.py", line 3005, in _run_raw_task
    return _run_raw_task(
           ^^^^^^^^^^^^^^
  File "/home/airflow/.local/lib/python3.12/site-packages/airflow/models/taskinstance.py", line 273, in _run_raw_task
    TaskInstance._execute_task_with_callbacks(
  File "/home/airflow/.local/lib/python3.12/site-packages/airflow/models/taskinstance.py", line 3159, in _execute_task_with_callbacks
    result = self._execute_task(context, task_orig)
             ^^^^^^^^^^^^^^^^^^^^^^^^^^^^^^^^^^^^^^
  File "/home/airflow/.local/lib/python3.12/site-packages/airflow/models/taskinstance.py", line 3183, in _execute_task
    return _execute_task(self, context, task_orig)
           ^^^^^^^^^^^^^^^^^^^^^^^^^^^^^^^^^^^^^^^
  File "/home/airflow/.local/lib/python3.12/site-packages/airflow/models/taskinstance.py", line 767, in _execute_task
    result = _execute_callable(context=context, **execute_callable_kwargs)
             ^^^^^^^^^^^^^^^^^^^^^^^^^^^^^^^^^^^^^^^^^^^^^^^^^^^^^^^^^^^^^
  File "/home/airflow/.local/lib/python3.12/site-packages/airflow/models/taskinstance.py", line 733, in _execute_callable
    return ExecutionCallableRunner(
           ^^^^^^^^^^^^^^^^^^^^^^^^
  File "/home/airflow/.local/lib/python3.12/site-packages/airflow/utils/operator_helpers.py", line 252, in run
    return self.func(*args, **kwargs)
           ^^^^^^^^^^^^^^^^^^^^^^^^^^
  File "/home/airflow/.local/lib/python3.12/site-packages/airflow/models/baseoperator.py", line 417, in wrapper
    return func(self, *args, **kwargs)
           ^^^^^^^^^^^^^^^^^^^^^^^^^^^
  File "/home/airflow/.local/lib/python3.12/site-packages/airflow/operators/python.py", line 238, in execute
    return_value = self.execute_callable()
                   ^^^^^^^^^^^^^^^^^^^^^^^
  File "/home/airflow/.local/lib/python3.12/site-packages/airflow/operators/python.py", line 256, in execute_callable
    return runner.run(*self.op_args, **self.op_kwargs)
           ^^^^^^^^^^^^^^^^^^^^^^^^^^^^^^^^^^^^^^^^^^^
  File "/home/airflow/.local/lib/python3.12/site-packages/airflow/utils/operator_helpers.py", line 252, in run
    return self.func(*args, **kwargs)
           ^^^^^^^^^^^^^^^^^^^^^^^^^^
  File "/opt/airflow/dags/llm_test.py", line 75, in get_next_batch
    if cursor:
       ^^^^^^
UnboundLocalError: cannot access local variable 'cursor' where it is not associated with a value
[2024-12-03T21:48:20.495+0000] {local_task_job_runner.py:266} INFO - Task exited with return code 1
[2024-12-03T21:48:20.512+0000] {taskinstance.py:3895} INFO - 0 downstream tasks scheduled from follow-on schedule check
[2024-12-03T21:48:20.515+0000] {local_task_job_runner.py:245} INFO - ::endgroup::
