[2024-12-06T15:14:31.991+0000] {local_task_job_runner.py:123} INFO - ::group::Pre task execution logs
[2024-12-06T15:14:32.003+0000] {taskinstance.py:2613} INFO - Dependencies all met for dep_context=non-requeueable deps ti=<TaskInstance: insert_cleaned_data.insert_cleaned_data manual__2024-12-06T15:14:28.637803+00:00 [queued]>
[2024-12-06T15:14:32.011+0000] {taskinstance.py:2613} INFO - Dependencies all met for dep_context=requeueable deps ti=<TaskInstance: insert_cleaned_data.insert_cleaned_data manual__2024-12-06T15:14:28.637803+00:00 [queued]>
[2024-12-06T15:14:32.011+0000] {taskinstance.py:2866} INFO - Starting attempt 1 of 4
[2024-12-06T15:14:32.023+0000] {taskinstance.py:2889} INFO - Executing <Task(PostgresOperator): insert_cleaned_data> on 2024-12-06 15:14:28.637803+00:00
[2024-12-06T15:14:32.028+0000] {warnings.py:112} WARNING - /home/***/.local/lib/python3.12/site-packages/***/task/task_runner/standard_task_runner.py:70: DeprecationWarning: This process (pid=2729) is multi-threaded, use of fork() may lead to deadlocks in the child.
  pid = os.fork()

[2024-12-06T15:14:32.030+0000] {standard_task_runner.py:72} INFO - Started process 2730 to run task
[2024-12-06T15:14:32.030+0000] {standard_task_runner.py:104} INFO - Running: ['***', 'tasks', 'run', 'insert_cleaned_data', 'insert_cleaned_data', 'manual__2024-12-06T15:14:28.637803+00:00', '--job-id', '1999', '--raw', '--subdir', 'DAGS_FOLDER/insert_cleaned_data.py', '--cfg-path', '/tmp/tmpkj5m27km']
[2024-12-06T15:14:32.031+0000] {standard_task_runner.py:105} INFO - Job 1999: Subtask insert_cleaned_data
[2024-12-06T15:14:32.067+0000] {task_command.py:467} INFO - Running <TaskInstance: insert_cleaned_data.insert_cleaned_data manual__2024-12-06T15:14:28.637803+00:00 [running]> on host cb0074367deb
[2024-12-06T15:14:32.127+0000] {taskinstance.py:3132} INFO - Exporting env vars: AIRFLOW_CTX_DAG_OWNER='artzsh' AIRFLOW_CTX_DAG_ID='insert_cleaned_data' AIRFLOW_CTX_TASK_ID='insert_cleaned_data' AIRFLOW_CTX_EXECUTION_DATE='2024-12-06T15:14:28.637803+00:00' AIRFLOW_CTX_TRY_NUMBER='1' AIRFLOW_CTX_DAG_RUN_ID='manual__2024-12-06T15:14:28.637803+00:00'
[2024-12-06T15:14:32.128+0000] {taskinstance.py:731} INFO - ::endgroup::
[2024-12-06T15:14:32.137+0000] {sql.py:278} INFO - Executing: 
        INSERT INTO "DDS"."final_table" (
            event_time, 
            event_type, 
            product_id, 
            category_id, 
            category_code, 
            brand, 
            price, 
            user_id, 
            user_session
        )
        SELECT 
            st.event_time, 
            st.event_type, 
            st.product_id, 
            st.category_id, 
            st.category_code, 
            st.brand, 
            st.price, 
            st.user_id, 
            st.user_session
        FROM "DDS-STG"."eCommerce_Oct" st
        JOIN "DDS"."brand_category_mapping_final" bcm
          ON st.brand = bcm.brand
         AND st.category_code = bcm.category_code;
    
[2024-12-06T15:14:32.143+0000] {base.py:84} INFO - Retrieving connection 'database_cloud'
[2024-12-06T15:14:32.149+0000] {base.py:84} INFO - Retrieving connection 'database_cloud'
[2024-12-06T15:14:32.784+0000] {sql.py:544} INFO - Running statement: 
        INSERT INTO "DDS"."final_table" (
            event_time, 
            event_type, 
            product_id, 
            category_id, 
            category_code, 
            brand, 
            price, 
            user_id, 
            user_session
        )
        SELECT 
            st.event_time, 
            st.event_type, 
            st.product_id, 
            st.category_id, 
            st.category_code, 
            st.brand, 
            st.price, 
            st.user_id, 
            st.user_session
        FROM "DDS-STG"."eCommerce_Oct" st
        JOIN "DDS"."brand_category_mapping_final" bcm
          ON st.brand = bcm.brand
         AND st.category_code = bcm.category_code;
    , parameters: None
[2024-12-06T15:15:31.567+0000] {taskinstance.py:3311} ERROR - Task failed with exception
Traceback (most recent call last):
  File "/home/airflow/.local/lib/python3.12/site-packages/airflow/models/taskinstance.py", line 767, in _execute_task
    result = _execute_callable(context=context, **execute_callable_kwargs)
             ^^^^^^^^^^^^^^^^^^^^^^^^^^^^^^^^^^^^^^^^^^^^^^^^^^^^^^^^^^^^^
  File "/home/airflow/.local/lib/python3.12/site-packages/airflow/models/taskinstance.py", line 733, in _execute_callable
    return ExecutionCallableRunner(
           ^^^^^^^^^^^^^^^^^^^^^^^^
  File "/home/airflow/.local/lib/python3.12/site-packages/airflow/utils/operator_helpers.py", line 252, in run
    return self.func(*args, **kwargs)
           ^^^^^^^^^^^^^^^^^^^^^^^^^^
  File "/home/airflow/.local/lib/python3.12/site-packages/airflow/models/baseoperator.py", line 417, in wrapper
    return func(self, *args, **kwargs)
           ^^^^^^^^^^^^^^^^^^^^^^^^^^^
  File "/home/airflow/.local/lib/python3.12/site-packages/airflow/providers/common/sql/operators/sql.py", line 284, in execute
    output = hook.run(
             ^^^^^^^^^
  File "/home/airflow/.local/lib/python3.12/site-packages/airflow/providers/common/sql/hooks/sql.py", line 489, in run
    self._run_command(cur, sql_statement, parameters)
  File "/home/airflow/.local/lib/python3.12/site-packages/airflow/providers/common/sql/hooks/sql.py", line 549, in _run_command
    cur.execute(sql_statement)
psycopg2.errors.NotNullViolation: null value in column "user_session" of relation "final_table" violates not-null constraint
DETAIL:  Failing row contains (2019-10-25 10:36:14 UTC, cart, 1004767, 2053013555631882655, electronics.smartphone, samsung, 246.52, 549825742, null).

[2024-12-06T15:15:31.582+0000] {taskinstance.py:1225} INFO - Marking task as UP_FOR_RETRY. dag_id=insert_cleaned_data, task_id=insert_cleaned_data, run_id=manual__2024-12-06T15:14:28.637803+00:00, execution_date=20241206T151428, start_date=20241206T151432, end_date=20241206T151531
[2024-12-06T15:15:31.595+0000] {taskinstance.py:340} INFO - ::group::Post task execution logs
[2024-12-06T15:15:31.595+0000] {standard_task_runner.py:124} ERROR - Failed to execute job 1999 for task insert_cleaned_data (null value in column "user_session" of relation "final_table" violates not-null constraint
DETAIL:  Failing row contains (2019-10-25 10:36:14 UTC, cart, 1004767, 2053013555631882655, electronics.smartphone, samsung, 246.52, 549825742, null).
; 2730)
Traceback (most recent call last):
  File "/home/airflow/.local/lib/python3.12/site-packages/airflow/task/task_runner/standard_task_runner.py", line 117, in _start_by_fork
    ret = args.func(args, dag=self.dag)
          ^^^^^^^^^^^^^^^^^^^^^^^^^^^^^
  File "/home/airflow/.local/lib/python3.12/site-packages/airflow/cli/cli_config.py", line 49, in command
    return func(*args, **kwargs)
           ^^^^^^^^^^^^^^^^^^^^^
  File "/home/airflow/.local/lib/python3.12/site-packages/airflow/utils/cli.py", line 116, in wrapper
    return f(*args, **kwargs)
           ^^^^^^^^^^^^^^^^^^
  File "/home/airflow/.local/lib/python3.12/site-packages/airflow/cli/commands/task_command.py", line 483, in task_run
    task_return_code = _run_task_by_selected_method(args, _dag, ti)
                       ^^^^^^^^^^^^^^^^^^^^^^^^^^^^^^^^^^^^^^^^^^^^
  File "/home/airflow/.local/lib/python3.12/site-packages/airflow/cli/commands/task_command.py", line 256, in _run_task_by_selected_method
    return _run_raw_task(args, ti)
           ^^^^^^^^^^^^^^^^^^^^^^^
  File "/home/airflow/.local/lib/python3.12/site-packages/airflow/cli/commands/task_command.py", line 341, in _run_raw_task
    return ti._run_raw_task(
           ^^^^^^^^^^^^^^^^^
  File "/home/airflow/.local/lib/python3.12/site-packages/airflow/utils/session.py", line 97, in wrapper
    return func(*args, session=session, **kwargs)
           ^^^^^^^^^^^^^^^^^^^^^^^^^^^^^^^^^^^^^^
  File "/home/airflow/.local/lib/python3.12/site-packages/airflow/models/taskinstance.py", line 3005, in _run_raw_task
    return _run_raw_task(
           ^^^^^^^^^^^^^^
  File "/home/airflow/.local/lib/python3.12/site-packages/airflow/models/taskinstance.py", line 273, in _run_raw_task
    TaskInstance._execute_task_with_callbacks(
  File "/home/airflow/.local/lib/python3.12/site-packages/airflow/models/taskinstance.py", line 3159, in _execute_task_with_callbacks
    result = self._execute_task(context, task_orig)
             ^^^^^^^^^^^^^^^^^^^^^^^^^^^^^^^^^^^^^^
  File "/home/airflow/.local/lib/python3.12/site-packages/airflow/models/taskinstance.py", line 3183, in _execute_task
    return _execute_task(self, context, task_orig)
           ^^^^^^^^^^^^^^^^^^^^^^^^^^^^^^^^^^^^^^^
  File "/home/airflow/.local/lib/python3.12/site-packages/airflow/models/taskinstance.py", line 767, in _execute_task
    result = _execute_callable(context=context, **execute_callable_kwargs)
             ^^^^^^^^^^^^^^^^^^^^^^^^^^^^^^^^^^^^^^^^^^^^^^^^^^^^^^^^^^^^^
  File "/home/airflow/.local/lib/python3.12/site-packages/airflow/models/taskinstance.py", line 733, in _execute_callable
    return ExecutionCallableRunner(
           ^^^^^^^^^^^^^^^^^^^^^^^^
  File "/home/airflow/.local/lib/python3.12/site-packages/airflow/utils/operator_helpers.py", line 252, in run
    return self.func(*args, **kwargs)
           ^^^^^^^^^^^^^^^^^^^^^^^^^^
  File "/home/airflow/.local/lib/python3.12/site-packages/airflow/models/baseoperator.py", line 417, in wrapper
    return func(self, *args, **kwargs)
           ^^^^^^^^^^^^^^^^^^^^^^^^^^^
  File "/home/airflow/.local/lib/python3.12/site-packages/airflow/providers/common/sql/operators/sql.py", line 284, in execute
    output = hook.run(
             ^^^^^^^^^
  File "/home/airflow/.local/lib/python3.12/site-packages/airflow/providers/common/sql/hooks/sql.py", line 489, in run
    self._run_command(cur, sql_statement, parameters)
  File "/home/airflow/.local/lib/python3.12/site-packages/airflow/providers/common/sql/hooks/sql.py", line 549, in _run_command
    cur.execute(sql_statement)
psycopg2.errors.NotNullViolation: null value in column "user_session" of relation "final_table" violates not-null constraint
DETAIL:  Failing row contains (2019-10-25 10:36:14 UTC, cart, 1004767, 2053013555631882655, electronics.smartphone, samsung, 246.52, 549825742, null).

[2024-12-06T15:15:31.603+0000] {local_task_job_runner.py:266} INFO - Task exited with return code 1
[2024-12-06T15:15:31.617+0000] {taskinstance.py:3895} INFO - 0 downstream tasks scheduled from follow-on schedule check
[2024-12-06T15:15:31.619+0000] {local_task_job_runner.py:245} INFO - ::endgroup::
