[2024-11-30T23:40:10.063+0000] {processor.py:186} INFO - Started process (PID=54) to work on /opt/airflow/dags/llm_test.py
[2024-11-30T23:40:10.064+0000] {processor.py:914} INFO - Processing file /opt/airflow/dags/llm_test.py for tasks to queue
[2024-11-30T23:40:10.070+0000] {logging_mixin.py:190} INFO - [2024-11-30T23:40:10.070+0000] {dagbag.py:588} INFO - Filling up the DagBag from /opt/airflow/dags/llm_test.py
[2024-11-30T23:40:10.716+0000] {logging_mixin.py:190} INFO - [2024-11-30T23:40:10.712+0000] {dagbag.py:387} ERROR - Failed to import: /opt/airflow/dags/llm_test.py
Traceback (most recent call last):
  File "/home/airflow/.local/lib/python3.12/site-packages/airflow/models/dagbag.py", line 383, in parse
    loader.exec_module(new_module)
  File "<frozen importlib._bootstrap_external>", line 995, in exec_module
  File "<frozen importlib._bootstrap>", line 488, in _call_with_frames_removed
  File "/opt/airflow/dags/llm_test.py", line 14, in <module>
    from g4f import Client
ModuleNotFoundError: No module named 'g4f'
[2024-11-30T23:40:10.717+0000] {processor.py:927} WARNING - No viable dags retrieved from /opt/airflow/dags/llm_test.py
[2024-11-30T23:40:10.736+0000] {processor.py:208} INFO - Processing /opt/airflow/dags/llm_test.py took 0.680 seconds
[2024-11-30T23:40:41.127+0000] {processor.py:186} INFO - Started process (PID=74) to work on /opt/airflow/dags/llm_test.py
[2024-11-30T23:40:41.128+0000] {processor.py:914} INFO - Processing file /opt/airflow/dags/llm_test.py for tasks to queue
[2024-11-30T23:40:41.130+0000] {logging_mixin.py:190} INFO - [2024-11-30T23:40:41.130+0000] {dagbag.py:588} INFO - Filling up the DagBag from /opt/airflow/dags/llm_test.py
[2024-11-30T23:40:41.605+0000] {logging_mixin.py:190} INFO - [2024-11-30T23:40:41.603+0000] {dagbag.py:387} ERROR - Failed to import: /opt/airflow/dags/llm_test.py
Traceback (most recent call last):
  File "/home/airflow/.local/lib/python3.12/site-packages/airflow/models/dagbag.py", line 383, in parse
    loader.exec_module(new_module)
  File "<frozen importlib._bootstrap_external>", line 995, in exec_module
  File "<frozen importlib._bootstrap>", line 488, in _call_with_frames_removed
  File "/opt/airflow/dags/llm_test.py", line 14, in <module>
    from g4f import Client
ModuleNotFoundError: No module named 'g4f'
[2024-11-30T23:40:41.606+0000] {processor.py:927} WARNING - No viable dags retrieved from /opt/airflow/dags/llm_test.py
[2024-11-30T23:40:41.619+0000] {processor.py:208} INFO - Processing /opt/airflow/dags/llm_test.py took 0.496 seconds
[2024-11-30T23:41:11.966+0000] {processor.py:186} INFO - Started process (PID=94) to work on /opt/airflow/dags/llm_test.py
[2024-11-30T23:41:11.966+0000] {processor.py:914} INFO - Processing file /opt/airflow/dags/llm_test.py for tasks to queue
[2024-11-30T23:41:11.968+0000] {logging_mixin.py:190} INFO - [2024-11-30T23:41:11.968+0000] {dagbag.py:588} INFO - Filling up the DagBag from /opt/airflow/dags/llm_test.py
[2024-11-30T23:41:12.321+0000] {logging_mixin.py:190} INFO - [2024-11-30T23:41:12.318+0000] {dagbag.py:387} ERROR - Failed to import: /opt/airflow/dags/llm_test.py
Traceback (most recent call last):
  File "/home/airflow/.local/lib/python3.12/site-packages/airflow/models/dagbag.py", line 383, in parse
    loader.exec_module(new_module)
  File "<frozen importlib._bootstrap_external>", line 995, in exec_module
  File "<frozen importlib._bootstrap>", line 488, in _call_with_frames_removed
  File "/opt/airflow/dags/llm_test.py", line 14, in <module>
    from g4f import Client
ModuleNotFoundError: No module named 'g4f'
[2024-11-30T23:41:12.322+0000] {processor.py:927} WARNING - No viable dags retrieved from /opt/airflow/dags/llm_test.py
[2024-11-30T23:41:12.338+0000] {processor.py:208} INFO - Processing /opt/airflow/dags/llm_test.py took 0.376 seconds
[2024-11-30T23:41:42.754+0000] {processor.py:186} INFO - Started process (PID=114) to work on /opt/airflow/dags/llm_test.py
[2024-11-30T23:41:42.755+0000] {processor.py:914} INFO - Processing file /opt/airflow/dags/llm_test.py for tasks to queue
[2024-11-30T23:41:42.757+0000] {logging_mixin.py:190} INFO - [2024-11-30T23:41:42.757+0000] {dagbag.py:588} INFO - Filling up the DagBag from /opt/airflow/dags/llm_test.py
[2024-11-30T23:41:43.126+0000] {logging_mixin.py:190} INFO - [2024-11-30T23:41:43.123+0000] {dagbag.py:387} ERROR - Failed to import: /opt/airflow/dags/llm_test.py
Traceback (most recent call last):
  File "/home/airflow/.local/lib/python3.12/site-packages/airflow/models/dagbag.py", line 383, in parse
    loader.exec_module(new_module)
  File "<frozen importlib._bootstrap_external>", line 995, in exec_module
  File "<frozen importlib._bootstrap>", line 488, in _call_with_frames_removed
  File "/opt/airflow/dags/llm_test.py", line 14, in <module>
    from g4f import Client
ModuleNotFoundError: No module named 'g4f'
[2024-11-30T23:41:43.126+0000] {processor.py:927} WARNING - No viable dags retrieved from /opt/airflow/dags/llm_test.py
[2024-11-30T23:41:43.140+0000] {processor.py:208} INFO - Processing /opt/airflow/dags/llm_test.py took 0.391 seconds
[2024-11-30T23:42:13.467+0000] {processor.py:186} INFO - Started process (PID=134) to work on /opt/airflow/dags/llm_test.py
[2024-11-30T23:42:13.468+0000] {processor.py:914} INFO - Processing file /opt/airflow/dags/llm_test.py for tasks to queue
[2024-11-30T23:42:13.470+0000] {logging_mixin.py:190} INFO - [2024-11-30T23:42:13.470+0000] {dagbag.py:588} INFO - Filling up the DagBag from /opt/airflow/dags/llm_test.py
[2024-11-30T23:42:14.075+0000] {logging_mixin.py:190} INFO - [2024-11-30T23:42:14.067+0000] {dagbag.py:387} ERROR - Failed to import: /opt/airflow/dags/llm_test.py
Traceback (most recent call last):
  File "/home/airflow/.local/lib/python3.12/site-packages/airflow/models/dagbag.py", line 383, in parse
    loader.exec_module(new_module)
  File "<frozen importlib._bootstrap_external>", line 995, in exec_module
  File "<frozen importlib._bootstrap>", line 488, in _call_with_frames_removed
  File "/opt/airflow/dags/llm_test.py", line 14, in <module>
    from g4f import Client
ModuleNotFoundError: No module named 'g4f'
[2024-11-30T23:42:14.077+0000] {processor.py:927} WARNING - No viable dags retrieved from /opt/airflow/dags/llm_test.py
[2024-11-30T23:42:14.101+0000] {processor.py:208} INFO - Processing /opt/airflow/dags/llm_test.py took 0.639 seconds
[2024-11-30T23:42:22.828+0000] {processor.py:186} INFO - Started process (PID=155) to work on /opt/airflow/dags/llm_test.py
[2024-11-30T23:42:22.829+0000] {processor.py:914} INFO - Processing file /opt/airflow/dags/llm_test.py for tasks to queue
[2024-11-30T23:42:22.832+0000] {logging_mixin.py:190} INFO - [2024-11-30T23:42:22.831+0000] {dagbag.py:588} INFO - Filling up the DagBag from /opt/airflow/dags/llm_test.py
[2024-11-30T23:42:23.086+0000] {logging_mixin.py:190} INFO - [2024-11-30T23:42:23.082+0000] {dagbag.py:387} ERROR - Failed to import: /opt/airflow/dags/llm_test.py
Traceback (most recent call last):
  File "/home/airflow/.local/lib/python3.12/site-packages/airflow/models/dagbag.py", line 383, in parse
    loader.exec_module(new_module)
  File "<frozen importlib._bootstrap_external>", line 995, in exec_module
  File "<frozen importlib._bootstrap>", line 488, in _call_with_frames_removed
  File "/opt/airflow/dags/llm_test.py", line 14, in <module>
    import g4f
ModuleNotFoundError: No module named 'g4f'
[2024-11-30T23:42:23.087+0000] {processor.py:927} WARNING - No viable dags retrieved from /opt/airflow/dags/llm_test.py
[2024-11-30T23:42:23.105+0000] {processor.py:208} INFO - Processing /opt/airflow/dags/llm_test.py took 0.281 seconds
[2024-11-30T23:42:53.268+0000] {processor.py:186} INFO - Started process (PID=175) to work on /opt/airflow/dags/llm_test.py
[2024-11-30T23:42:53.269+0000] {processor.py:914} INFO - Processing file /opt/airflow/dags/llm_test.py for tasks to queue
[2024-11-30T23:42:53.271+0000] {logging_mixin.py:190} INFO - [2024-11-30T23:42:53.270+0000] {dagbag.py:588} INFO - Filling up the DagBag from /opt/airflow/dags/llm_test.py
[2024-11-30T23:42:53.493+0000] {logging_mixin.py:190} INFO - [2024-11-30T23:42:53.489+0000] {dagbag.py:387} ERROR - Failed to import: /opt/airflow/dags/llm_test.py
Traceback (most recent call last):
  File "/home/airflow/.local/lib/python3.12/site-packages/airflow/models/dagbag.py", line 383, in parse
    loader.exec_module(new_module)
  File "<frozen importlib._bootstrap_external>", line 995, in exec_module
  File "<frozen importlib._bootstrap>", line 488, in _call_with_frames_removed
  File "/opt/airflow/dags/llm_test.py", line 14, in <module>
    import g4f
ModuleNotFoundError: No module named 'g4f'
[2024-11-30T23:42:53.493+0000] {processor.py:927} WARNING - No viable dags retrieved from /opt/airflow/dags/llm_test.py
[2024-11-30T23:42:53.507+0000] {processor.py:208} INFO - Processing /opt/airflow/dags/llm_test.py took 0.244 seconds
[2024-11-30T23:43:23.636+0000] {processor.py:186} INFO - Started process (PID=195) to work on /opt/airflow/dags/llm_test.py
[2024-11-30T23:43:23.637+0000] {processor.py:914} INFO - Processing file /opt/airflow/dags/llm_test.py for tasks to queue
[2024-11-30T23:43:23.639+0000] {logging_mixin.py:190} INFO - [2024-11-30T23:43:23.639+0000] {dagbag.py:588} INFO - Filling up the DagBag from /opt/airflow/dags/llm_test.py
[2024-11-30T23:43:23.875+0000] {logging_mixin.py:190} INFO - [2024-11-30T23:43:23.870+0000] {dagbag.py:387} ERROR - Failed to import: /opt/airflow/dags/llm_test.py
Traceback (most recent call last):
  File "/home/airflow/.local/lib/python3.12/site-packages/airflow/models/dagbag.py", line 383, in parse
    loader.exec_module(new_module)
  File "<frozen importlib._bootstrap_external>", line 995, in exec_module
  File "<frozen importlib._bootstrap>", line 488, in _call_with_frames_removed
  File "/opt/airflow/dags/llm_test.py", line 14, in <module>
    import g4f
ModuleNotFoundError: No module named 'g4f'
[2024-11-30T23:43:23.876+0000] {processor.py:927} WARNING - No viable dags retrieved from /opt/airflow/dags/llm_test.py
[2024-11-30T23:43:23.892+0000] {processor.py:208} INFO - Processing /opt/airflow/dags/llm_test.py took 0.261 seconds
[2024-11-30T23:43:54.083+0000] {processor.py:186} INFO - Started process (PID=215) to work on /opt/airflow/dags/llm_test.py
[2024-11-30T23:43:54.084+0000] {processor.py:914} INFO - Processing file /opt/airflow/dags/llm_test.py for tasks to queue
[2024-11-30T23:43:54.086+0000] {logging_mixin.py:190} INFO - [2024-11-30T23:43:54.086+0000] {dagbag.py:588} INFO - Filling up the DagBag from /opt/airflow/dags/llm_test.py
[2024-11-30T23:43:54.325+0000] {logging_mixin.py:190} INFO - [2024-11-30T23:43:54.321+0000] {dagbag.py:387} ERROR - Failed to import: /opt/airflow/dags/llm_test.py
Traceback (most recent call last):
  File "/home/airflow/.local/lib/python3.12/site-packages/airflow/models/dagbag.py", line 383, in parse
    loader.exec_module(new_module)
  File "<frozen importlib._bootstrap_external>", line 995, in exec_module
  File "<frozen importlib._bootstrap>", line 488, in _call_with_frames_removed
  File "/opt/airflow/dags/llm_test.py", line 14, in <module>
    import g4f
ModuleNotFoundError: No module named 'g4f'
[2024-11-30T23:43:54.326+0000] {processor.py:927} WARNING - No viable dags retrieved from /opt/airflow/dags/llm_test.py
[2024-11-30T23:43:54.339+0000] {processor.py:208} INFO - Processing /opt/airflow/dags/llm_test.py took 0.262 seconds
[2024-11-30T23:44:24.669+0000] {processor.py:186} INFO - Started process (PID=235) to work on /opt/airflow/dags/llm_test.py
[2024-11-30T23:44:24.670+0000] {processor.py:914} INFO - Processing file /opt/airflow/dags/llm_test.py for tasks to queue
[2024-11-30T23:44:24.672+0000] {logging_mixin.py:190} INFO - [2024-11-30T23:44:24.671+0000] {dagbag.py:588} INFO - Filling up the DagBag from /opt/airflow/dags/llm_test.py
[2024-11-30T23:44:24.924+0000] {logging_mixin.py:190} INFO - [2024-11-30T23:44:24.921+0000] {dagbag.py:387} ERROR - Failed to import: /opt/airflow/dags/llm_test.py
Traceback (most recent call last):
  File "/home/airflow/.local/lib/python3.12/site-packages/airflow/models/dagbag.py", line 383, in parse
    loader.exec_module(new_module)
  File "<frozen importlib._bootstrap_external>", line 995, in exec_module
  File "<frozen importlib._bootstrap>", line 488, in _call_with_frames_removed
  File "/opt/airflow/dags/llm_test.py", line 14, in <module>
    import g4f
ModuleNotFoundError: No module named 'g4f'
[2024-11-30T23:44:24.925+0000] {processor.py:927} WARNING - No viable dags retrieved from /opt/airflow/dags/llm_test.py
[2024-11-30T23:44:24.941+0000] {processor.py:208} INFO - Processing /opt/airflow/dags/llm_test.py took 0.276 seconds
[2024-11-30T23:44:55.273+0000] {processor.py:186} INFO - Started process (PID=255) to work on /opt/airflow/dags/llm_test.py
[2024-11-30T23:44:55.274+0000] {processor.py:914} INFO - Processing file /opt/airflow/dags/llm_test.py for tasks to queue
[2024-11-30T23:44:55.276+0000] {logging_mixin.py:190} INFO - [2024-11-30T23:44:55.275+0000] {dagbag.py:588} INFO - Filling up the DagBag from /opt/airflow/dags/llm_test.py
[2024-11-30T23:44:55.498+0000] {logging_mixin.py:190} INFO - [2024-11-30T23:44:55.495+0000] {dagbag.py:387} ERROR - Failed to import: /opt/airflow/dags/llm_test.py
Traceback (most recent call last):
  File "/home/airflow/.local/lib/python3.12/site-packages/airflow/models/dagbag.py", line 383, in parse
    loader.exec_module(new_module)
  File "<frozen importlib._bootstrap_external>", line 995, in exec_module
  File "<frozen importlib._bootstrap>", line 488, in _call_with_frames_removed
  File "/opt/airflow/dags/llm_test.py", line 14, in <module>
    import g4f
ModuleNotFoundError: No module named 'g4f'
[2024-11-30T23:44:55.499+0000] {processor.py:927} WARNING - No viable dags retrieved from /opt/airflow/dags/llm_test.py
[2024-11-30T23:44:55.513+0000] {processor.py:208} INFO - Processing /opt/airflow/dags/llm_test.py took 0.245 seconds
[2024-11-30T23:45:25.871+0000] {processor.py:186} INFO - Started process (PID=275) to work on /opt/airflow/dags/llm_test.py
[2024-11-30T23:45:25.873+0000] {processor.py:914} INFO - Processing file /opt/airflow/dags/llm_test.py for tasks to queue
[2024-11-30T23:45:25.877+0000] {logging_mixin.py:190} INFO - [2024-11-30T23:45:25.876+0000] {dagbag.py:588} INFO - Filling up the DagBag from /opt/airflow/dags/llm_test.py
[2024-11-30T23:45:26.151+0000] {logging_mixin.py:190} INFO - [2024-11-30T23:45:26.148+0000] {dagbag.py:387} ERROR - Failed to import: /opt/airflow/dags/llm_test.py
Traceback (most recent call last):
  File "/home/airflow/.local/lib/python3.12/site-packages/airflow/models/dagbag.py", line 383, in parse
    loader.exec_module(new_module)
  File "<frozen importlib._bootstrap_external>", line 995, in exec_module
  File "<frozen importlib._bootstrap>", line 488, in _call_with_frames_removed
  File "/opt/airflow/dags/llm_test.py", line 14, in <module>
    import g4f
ModuleNotFoundError: No module named 'g4f'
[2024-11-30T23:45:26.152+0000] {processor.py:927} WARNING - No viable dags retrieved from /opt/airflow/dags/llm_test.py
[2024-11-30T23:45:26.165+0000] {processor.py:208} INFO - Processing /opt/airflow/dags/llm_test.py took 0.304 seconds
[2024-11-30T23:45:56.558+0000] {processor.py:186} INFO - Started process (PID=295) to work on /opt/airflow/dags/llm_test.py
[2024-11-30T23:45:56.559+0000] {processor.py:914} INFO - Processing file /opt/airflow/dags/llm_test.py for tasks to queue
[2024-11-30T23:45:56.561+0000] {logging_mixin.py:190} INFO - [2024-11-30T23:45:56.561+0000] {dagbag.py:588} INFO - Filling up the DagBag from /opt/airflow/dags/llm_test.py
[2024-11-30T23:45:56.794+0000] {logging_mixin.py:190} INFO - [2024-11-30T23:45:56.791+0000] {dagbag.py:387} ERROR - Failed to import: /opt/airflow/dags/llm_test.py
Traceback (most recent call last):
  File "/home/airflow/.local/lib/python3.12/site-packages/airflow/models/dagbag.py", line 383, in parse
    loader.exec_module(new_module)
  File "<frozen importlib._bootstrap_external>", line 995, in exec_module
  File "<frozen importlib._bootstrap>", line 488, in _call_with_frames_removed
  File "/opt/airflow/dags/llm_test.py", line 14, in <module>
    import g4f
ModuleNotFoundError: No module named 'g4f'
[2024-11-30T23:45:56.795+0000] {processor.py:927} WARNING - No viable dags retrieved from /opt/airflow/dags/llm_test.py
[2024-11-30T23:45:56.811+0000] {processor.py:208} INFO - Processing /opt/airflow/dags/llm_test.py took 0.258 seconds
[2024-11-30T23:46:27.556+0000] {processor.py:186} INFO - Started process (PID=315) to work on /opt/airflow/dags/llm_test.py
[2024-11-30T23:46:27.556+0000] {processor.py:914} INFO - Processing file /opt/airflow/dags/llm_test.py for tasks to queue
[2024-11-30T23:46:27.558+0000] {logging_mixin.py:190} INFO - [2024-11-30T23:46:27.558+0000] {dagbag.py:588} INFO - Filling up the DagBag from /opt/airflow/dags/llm_test.py
[2024-11-30T23:46:27.775+0000] {logging_mixin.py:190} INFO - [2024-11-30T23:46:27.772+0000] {dagbag.py:387} ERROR - Failed to import: /opt/airflow/dags/llm_test.py
Traceback (most recent call last):
  File "/home/airflow/.local/lib/python3.12/site-packages/airflow/models/dagbag.py", line 383, in parse
    loader.exec_module(new_module)
  File "<frozen importlib._bootstrap_external>", line 995, in exec_module
  File "<frozen importlib._bootstrap>", line 488, in _call_with_frames_removed
  File "/opt/airflow/dags/llm_test.py", line 14, in <module>
    import g4f
ModuleNotFoundError: No module named 'g4f'
[2024-11-30T23:46:27.777+0000] {processor.py:927} WARNING - No viable dags retrieved from /opt/airflow/dags/llm_test.py
[2024-11-30T23:46:27.790+0000] {processor.py:208} INFO - Processing /opt/airflow/dags/llm_test.py took 0.240 seconds
[2024-11-30T23:46:58.183+0000] {processor.py:186} INFO - Started process (PID=335) to work on /opt/airflow/dags/llm_test.py
[2024-11-30T23:46:58.184+0000] {processor.py:914} INFO - Processing file /opt/airflow/dags/llm_test.py for tasks to queue
[2024-11-30T23:46:58.186+0000] {logging_mixin.py:190} INFO - [2024-11-30T23:46:58.186+0000] {dagbag.py:588} INFO - Filling up the DagBag from /opt/airflow/dags/llm_test.py
[2024-11-30T23:46:58.425+0000] {logging_mixin.py:190} INFO - [2024-11-30T23:46:58.422+0000] {dagbag.py:387} ERROR - Failed to import: /opt/airflow/dags/llm_test.py
Traceback (most recent call last):
  File "/home/airflow/.local/lib/python3.12/site-packages/airflow/models/dagbag.py", line 383, in parse
    loader.exec_module(new_module)
  File "<frozen importlib._bootstrap_external>", line 995, in exec_module
  File "<frozen importlib._bootstrap>", line 488, in _call_with_frames_removed
  File "/opt/airflow/dags/llm_test.py", line 14, in <module>
    import g4f
ModuleNotFoundError: No module named 'g4f'
[2024-11-30T23:46:58.426+0000] {processor.py:927} WARNING - No viable dags retrieved from /opt/airflow/dags/llm_test.py
[2024-11-30T23:46:58.441+0000] {processor.py:208} INFO - Processing /opt/airflow/dags/llm_test.py took 0.262 seconds
[2024-11-30T23:48:01.787+0000] {processor.py:186} INFO - Started process (PID=87) to work on /opt/airflow/dags/llm_test.py
[2024-11-30T23:48:01.788+0000] {processor.py:914} INFO - Processing file /opt/airflow/dags/llm_test.py for tasks to queue
[2024-11-30T23:48:01.792+0000] {logging_mixin.py:190} INFO - [2024-11-30T23:48:01.791+0000] {dagbag.py:588} INFO - Filling up the DagBag from /opt/airflow/dags/llm_test.py
[2024-11-30T23:48:03.528+0000] {logging_mixin.py:190} INFO - [2024-11-30T23:48:03.520+0000] {dagbag.py:387} ERROR - Failed to import: /opt/airflow/dags/llm_test.py
Traceback (most recent call last):
  File "/home/airflow/.local/lib/python3.12/site-packages/airflow/models/dagbag.py", line 383, in parse
    loader.exec_module(new_module)
  File "<frozen importlib._bootstrap_external>", line 995, in exec_module
  File "<frozen importlib._bootstrap>", line 488, in _call_with_frames_removed
  File "/opt/airflow/dags/llm_test.py", line 299, in <module>
    check_completion >> TriggerDagRunOperator(
                        ^^^^^^^^^^^^^^^^^^^^^^
  File "/home/airflow/.local/lib/python3.12/site-packages/airflow/models/baseoperator.py", line 501, in apply_defaults
    result = func(self, **kwargs, default_args=default_args)
             ^^^^^^^^^^^^^^^^^^^^^^^^^^^^^^^^^^^^^^^^^^^^^^^
  File "/home/airflow/.local/lib/python3.12/site-packages/airflow/operators/trigger_dagrun.py", line 145, in __init__
    super().__init__(**kwargs)
  File "/home/airflow/.local/lib/python3.12/site-packages/airflow/models/baseoperator.py", line 501, in apply_defaults
    result = func(self, **kwargs, default_args=default_args)
             ^^^^^^^^^^^^^^^^^^^^^^^^^^^^^^^^^^^^^^^^^^^^^^^
  File "/home/airflow/.local/lib/python3.12/site-packages/airflow/models/baseoperator.py", line 949, in __init__
    raise AirflowException(
airflow.exceptions.AirflowException: Invalid arguments were passed to TriggerDagRunOperator (task_id: conditionally_trigger_next_run). Invalid arguments were:
**kwargs: {'python_callable': <function <lambda> at 0x7f7ca6966f20>}
[2024-11-30T23:48:03.530+0000] {processor.py:927} WARNING - No viable dags retrieved from /opt/airflow/dags/llm_test.py
[2024-11-30T23:48:03.567+0000] {processor.py:208} INFO - Processing /opt/airflow/dags/llm_test.py took 1.789 seconds
[2024-11-30T23:48:33.849+0000] {processor.py:186} INFO - Started process (PID=109) to work on /opt/airflow/dags/llm_test.py
[2024-11-30T23:48:33.851+0000] {processor.py:914} INFO - Processing file /opt/airflow/dags/llm_test.py for tasks to queue
[2024-11-30T23:48:33.855+0000] {logging_mixin.py:190} INFO - [2024-11-30T23:48:33.855+0000] {dagbag.py:588} INFO - Filling up the DagBag from /opt/airflow/dags/llm_test.py
[2024-11-30T23:48:34.458+0000] {logging_mixin.py:190} INFO - [2024-11-30T23:48:34.454+0000] {dagbag.py:387} ERROR - Failed to import: /opt/airflow/dags/llm_test.py
Traceback (most recent call last):
  File "/home/airflow/.local/lib/python3.12/site-packages/airflow/models/dagbag.py", line 383, in parse
    loader.exec_module(new_module)
  File "<frozen importlib._bootstrap_external>", line 995, in exec_module
  File "<frozen importlib._bootstrap>", line 488, in _call_with_frames_removed
  File "/opt/airflow/dags/llm_test.py", line 299, in <module>
    check_completion >> TriggerDagRunOperator(
                        ^^^^^^^^^^^^^^^^^^^^^^
  File "/home/airflow/.local/lib/python3.12/site-packages/airflow/models/baseoperator.py", line 501, in apply_defaults
    result = func(self, **kwargs, default_args=default_args)
             ^^^^^^^^^^^^^^^^^^^^^^^^^^^^^^^^^^^^^^^^^^^^^^^
  File "/home/airflow/.local/lib/python3.12/site-packages/airflow/operators/trigger_dagrun.py", line 145, in __init__
    super().__init__(**kwargs)
  File "/home/airflow/.local/lib/python3.12/site-packages/airflow/models/baseoperator.py", line 501, in apply_defaults
    result = func(self, **kwargs, default_args=default_args)
             ^^^^^^^^^^^^^^^^^^^^^^^^^^^^^^^^^^^^^^^^^^^^^^^
  File "/home/airflow/.local/lib/python3.12/site-packages/airflow/models/baseoperator.py", line 949, in __init__
    raise AirflowException(
airflow.exceptions.AirflowException: Invalid arguments were passed to TriggerDagRunOperator (task_id: conditionally_trigger_next_run). Invalid arguments were:
**kwargs: {'python_callable': <function <lambda> at 0x7f7ca6934540>}
[2024-11-30T23:48:34.459+0000] {processor.py:927} WARNING - No viable dags retrieved from /opt/airflow/dags/llm_test.py
[2024-11-30T23:48:34.476+0000] {processor.py:208} INFO - Processing /opt/airflow/dags/llm_test.py took 0.638 seconds
[2024-11-30T23:49:04.722+0000] {processor.py:186} INFO - Started process (PID=129) to work on /opt/airflow/dags/llm_test.py
[2024-11-30T23:49:04.723+0000] {processor.py:914} INFO - Processing file /opt/airflow/dags/llm_test.py for tasks to queue
[2024-11-30T23:49:04.725+0000] {logging_mixin.py:190} INFO - [2024-11-30T23:49:04.725+0000] {dagbag.py:588} INFO - Filling up the DagBag from /opt/airflow/dags/llm_test.py
[2024-11-30T23:49:05.209+0000] {logging_mixin.py:190} INFO - [2024-11-30T23:49:05.206+0000] {dagbag.py:387} ERROR - Failed to import: /opt/airflow/dags/llm_test.py
Traceback (most recent call last):
  File "/home/airflow/.local/lib/python3.12/site-packages/airflow/models/dagbag.py", line 383, in parse
    loader.exec_module(new_module)
  File "<frozen importlib._bootstrap_external>", line 995, in exec_module
  File "<frozen importlib._bootstrap>", line 488, in _call_with_frames_removed
  File "/opt/airflow/dags/llm_test.py", line 299, in <module>
    check_completion >> TriggerDagRunOperator(
                        ^^^^^^^^^^^^^^^^^^^^^^
  File "/home/airflow/.local/lib/python3.12/site-packages/airflow/models/baseoperator.py", line 501, in apply_defaults
    result = func(self, **kwargs, default_args=default_args)
             ^^^^^^^^^^^^^^^^^^^^^^^^^^^^^^^^^^^^^^^^^^^^^^^
  File "/home/airflow/.local/lib/python3.12/site-packages/airflow/operators/trigger_dagrun.py", line 145, in __init__
    super().__init__(**kwargs)
  File "/home/airflow/.local/lib/python3.12/site-packages/airflow/models/baseoperator.py", line 501, in apply_defaults
    result = func(self, **kwargs, default_args=default_args)
             ^^^^^^^^^^^^^^^^^^^^^^^^^^^^^^^^^^^^^^^^^^^^^^^
  File "/home/airflow/.local/lib/python3.12/site-packages/airflow/models/baseoperator.py", line 949, in __init__
    raise AirflowException(
airflow.exceptions.AirflowException: Invalid arguments were passed to TriggerDagRunOperator (task_id: conditionally_trigger_next_run). Invalid arguments were:
**kwargs: {'python_callable': <function <lambda> at 0x7f7ca6934540>}
[2024-11-30T23:49:05.210+0000] {processor.py:927} WARNING - No viable dags retrieved from /opt/airflow/dags/llm_test.py
[2024-11-30T23:49:05.224+0000] {processor.py:208} INFO - Processing /opt/airflow/dags/llm_test.py took 0.507 seconds
[2024-11-30T23:49:35.360+0000] {processor.py:186} INFO - Started process (PID=149) to work on /opt/airflow/dags/llm_test.py
[2024-11-30T23:49:35.361+0000] {processor.py:914} INFO - Processing file /opt/airflow/dags/llm_test.py for tasks to queue
[2024-11-30T23:49:35.363+0000] {logging_mixin.py:190} INFO - [2024-11-30T23:49:35.363+0000] {dagbag.py:588} INFO - Filling up the DagBag from /opt/airflow/dags/llm_test.py
[2024-11-30T23:49:35.870+0000] {logging_mixin.py:190} INFO - [2024-11-30T23:49:35.867+0000] {dagbag.py:387} ERROR - Failed to import: /opt/airflow/dags/llm_test.py
Traceback (most recent call last):
  File "/home/airflow/.local/lib/python3.12/site-packages/airflow/models/dagbag.py", line 383, in parse
    loader.exec_module(new_module)
  File "<frozen importlib._bootstrap_external>", line 995, in exec_module
  File "<frozen importlib._bootstrap>", line 488, in _call_with_frames_removed
  File "/opt/airflow/dags/llm_test.py", line 299, in <module>
    check_completion >> TriggerDagRunOperator(
                        ^^^^^^^^^^^^^^^^^^^^^^
  File "/home/airflow/.local/lib/python3.12/site-packages/airflow/models/baseoperator.py", line 501, in apply_defaults
    result = func(self, **kwargs, default_args=default_args)
             ^^^^^^^^^^^^^^^^^^^^^^^^^^^^^^^^^^^^^^^^^^^^^^^
  File "/home/airflow/.local/lib/python3.12/site-packages/airflow/operators/trigger_dagrun.py", line 145, in __init__
    super().__init__(**kwargs)
  File "/home/airflow/.local/lib/python3.12/site-packages/airflow/models/baseoperator.py", line 501, in apply_defaults
    result = func(self, **kwargs, default_args=default_args)
             ^^^^^^^^^^^^^^^^^^^^^^^^^^^^^^^^^^^^^^^^^^^^^^^
  File "/home/airflow/.local/lib/python3.12/site-packages/airflow/models/baseoperator.py", line 949, in __init__
    raise AirflowException(
airflow.exceptions.AirflowException: Invalid arguments were passed to TriggerDagRunOperator (task_id: conditionally_trigger_next_run). Invalid arguments were:
**kwargs: {'python_callable': <function <lambda> at 0x7f7ca6934540>}
[2024-11-30T23:49:35.871+0000] {processor.py:927} WARNING - No viable dags retrieved from /opt/airflow/dags/llm_test.py
[2024-11-30T23:49:35.884+0000] {processor.py:208} INFO - Processing /opt/airflow/dags/llm_test.py took 0.528 seconds
[2024-11-30T23:50:06.131+0000] {processor.py:186} INFO - Started process (PID=175) to work on /opt/airflow/dags/llm_test.py
[2024-11-30T23:50:06.132+0000] {processor.py:914} INFO - Processing file /opt/airflow/dags/llm_test.py for tasks to queue
[2024-11-30T23:50:06.134+0000] {logging_mixin.py:190} INFO - [2024-11-30T23:50:06.134+0000] {dagbag.py:588} INFO - Filling up the DagBag from /opt/airflow/dags/llm_test.py
[2024-11-30T23:50:06.627+0000] {logging_mixin.py:190} INFO - [2024-11-30T23:50:06.624+0000] {dagbag.py:387} ERROR - Failed to import: /opt/airflow/dags/llm_test.py
Traceback (most recent call last):
  File "/home/airflow/.local/lib/python3.12/site-packages/airflow/models/dagbag.py", line 383, in parse
    loader.exec_module(new_module)
  File "<frozen importlib._bootstrap_external>", line 995, in exec_module
  File "<frozen importlib._bootstrap>", line 488, in _call_with_frames_removed
  File "/opt/airflow/dags/llm_test.py", line 299, in <module>
    check_completion >> TriggerDagRunOperator(
                        ^^^^^^^^^^^^^^^^^^^^^^
  File "/home/airflow/.local/lib/python3.12/site-packages/airflow/models/baseoperator.py", line 501, in apply_defaults
    result = func(self, **kwargs, default_args=default_args)
             ^^^^^^^^^^^^^^^^^^^^^^^^^^^^^^^^^^^^^^^^^^^^^^^
  File "/home/airflow/.local/lib/python3.12/site-packages/airflow/operators/trigger_dagrun.py", line 145, in __init__
    super().__init__(**kwargs)
  File "/home/airflow/.local/lib/python3.12/site-packages/airflow/models/baseoperator.py", line 501, in apply_defaults
    result = func(self, **kwargs, default_args=default_args)
             ^^^^^^^^^^^^^^^^^^^^^^^^^^^^^^^^^^^^^^^^^^^^^^^
  File "/home/airflow/.local/lib/python3.12/site-packages/airflow/models/baseoperator.py", line 949, in __init__
    raise AirflowException(
airflow.exceptions.AirflowException: Invalid arguments were passed to TriggerDagRunOperator (task_id: conditionally_trigger_next_run). Invalid arguments were:
**kwargs: {'python_callable': <function <lambda> at 0x7f7ca6934220>}
[2024-11-30T23:50:06.628+0000] {processor.py:927} WARNING - No viable dags retrieved from /opt/airflow/dags/llm_test.py
[2024-11-30T23:50:06.643+0000] {processor.py:208} INFO - Processing /opt/airflow/dags/llm_test.py took 0.516 seconds
[2024-11-30T23:50:37.324+0000] {processor.py:186} INFO - Started process (PID=195) to work on /opt/airflow/dags/llm_test.py
[2024-11-30T23:50:37.325+0000] {processor.py:914} INFO - Processing file /opt/airflow/dags/llm_test.py for tasks to queue
[2024-11-30T23:50:37.327+0000] {logging_mixin.py:190} INFO - [2024-11-30T23:50:37.327+0000] {dagbag.py:588} INFO - Filling up the DagBag from /opt/airflow/dags/llm_test.py
[2024-11-30T23:50:37.744+0000] {logging_mixin.py:190} INFO - [2024-11-30T23:50:37.741+0000] {dagbag.py:387} ERROR - Failed to import: /opt/airflow/dags/llm_test.py
Traceback (most recent call last):
  File "/home/airflow/.local/lib/python3.12/site-packages/airflow/models/dagbag.py", line 383, in parse
    loader.exec_module(new_module)
  File "<frozen importlib._bootstrap_external>", line 995, in exec_module
  File "<frozen importlib._bootstrap>", line 488, in _call_with_frames_removed
  File "/opt/airflow/dags/llm_test.py", line 299, in <module>
    check_completion >> TriggerDagRunOperator(
                        ^^^^^^^^^^^^^^^^^^^^^^
  File "/home/airflow/.local/lib/python3.12/site-packages/airflow/models/baseoperator.py", line 501, in apply_defaults
    result = func(self, **kwargs, default_args=default_args)
             ^^^^^^^^^^^^^^^^^^^^^^^^^^^^^^^^^^^^^^^^^^^^^^^
  File "/home/airflow/.local/lib/python3.12/site-packages/airflow/operators/trigger_dagrun.py", line 145, in __init__
    super().__init__(**kwargs)
  File "/home/airflow/.local/lib/python3.12/site-packages/airflow/models/baseoperator.py", line 501, in apply_defaults
    result = func(self, **kwargs, default_args=default_args)
             ^^^^^^^^^^^^^^^^^^^^^^^^^^^^^^^^^^^^^^^^^^^^^^^
  File "/home/airflow/.local/lib/python3.12/site-packages/airflow/models/baseoperator.py", line 949, in __init__
    raise AirflowException(
airflow.exceptions.AirflowException: Invalid arguments were passed to TriggerDagRunOperator (task_id: conditionally_trigger_next_run). Invalid arguments were:
**kwargs: {'python_callable': <function <lambda> at 0x7f7ca6934220>}
[2024-11-30T23:50:37.745+0000] {processor.py:927} WARNING - No viable dags retrieved from /opt/airflow/dags/llm_test.py
[2024-11-30T23:50:37.761+0000] {processor.py:208} INFO - Processing /opt/airflow/dags/llm_test.py took 0.440 seconds
[2024-11-30T23:51:08.020+0000] {processor.py:186} INFO - Started process (PID=217) to work on /opt/airflow/dags/llm_test.py
[2024-11-30T23:51:08.021+0000] {processor.py:914} INFO - Processing file /opt/airflow/dags/llm_test.py for tasks to queue
[2024-11-30T23:51:08.022+0000] {logging_mixin.py:190} INFO - [2024-11-30T23:51:08.022+0000] {dagbag.py:588} INFO - Filling up the DagBag from /opt/airflow/dags/llm_test.py
[2024-11-30T23:51:08.509+0000] {logging_mixin.py:190} INFO - [2024-11-30T23:51:08.506+0000] {dagbag.py:387} ERROR - Failed to import: /opt/airflow/dags/llm_test.py
Traceback (most recent call last):
  File "/home/airflow/.local/lib/python3.12/site-packages/airflow/models/dagbag.py", line 383, in parse
    loader.exec_module(new_module)
  File "<frozen importlib._bootstrap_external>", line 995, in exec_module
  File "<frozen importlib._bootstrap>", line 488, in _call_with_frames_removed
  File "/opt/airflow/dags/llm_test.py", line 299, in <module>
    check_completion >> TriggerDagRunOperator(
                        ^^^^^^^^^^^^^^^^^^^^^^
  File "/home/airflow/.local/lib/python3.12/site-packages/airflow/models/baseoperator.py", line 501, in apply_defaults
    result = func(self, **kwargs, default_args=default_args)
             ^^^^^^^^^^^^^^^^^^^^^^^^^^^^^^^^^^^^^^^^^^^^^^^
  File "/home/airflow/.local/lib/python3.12/site-packages/airflow/operators/trigger_dagrun.py", line 145, in __init__
    super().__init__(**kwargs)
  File "/home/airflow/.local/lib/python3.12/site-packages/airflow/models/baseoperator.py", line 501, in apply_defaults
    result = func(self, **kwargs, default_args=default_args)
             ^^^^^^^^^^^^^^^^^^^^^^^^^^^^^^^^^^^^^^^^^^^^^^^
  File "/home/airflow/.local/lib/python3.12/site-packages/airflow/models/baseoperator.py", line 949, in __init__
    raise AirflowException(
airflow.exceptions.AirflowException: Invalid arguments were passed to TriggerDagRunOperator (task_id: conditionally_trigger_next_run). Invalid arguments were:
**kwargs: {'python_callable': <function <lambda> at 0x7f7ca6934220>}
[2024-11-30T23:51:08.510+0000] {processor.py:927} WARNING - No viable dags retrieved from /opt/airflow/dags/llm_test.py
[2024-11-30T23:51:08.525+0000] {processor.py:208} INFO - Processing /opt/airflow/dags/llm_test.py took 0.510 seconds
[2024-11-30T23:51:38.844+0000] {processor.py:186} INFO - Started process (PID=235) to work on /opt/airflow/dags/llm_test.py
[2024-11-30T23:51:38.847+0000] {processor.py:914} INFO - Processing file /opt/airflow/dags/llm_test.py for tasks to queue
[2024-11-30T23:51:38.852+0000] {logging_mixin.py:190} INFO - [2024-11-30T23:51:38.851+0000] {dagbag.py:588} INFO - Filling up the DagBag from /opt/airflow/dags/llm_test.py
[2024-11-30T23:51:39.342+0000] {logging_mixin.py:190} INFO - [2024-11-30T23:51:39.339+0000] {dagbag.py:387} ERROR - Failed to import: /opt/airflow/dags/llm_test.py
Traceback (most recent call last):
  File "/home/airflow/.local/lib/python3.12/site-packages/airflow/models/dagbag.py", line 383, in parse
    loader.exec_module(new_module)
  File "<frozen importlib._bootstrap_external>", line 995, in exec_module
  File "<frozen importlib._bootstrap>", line 488, in _call_with_frames_removed
  File "/opt/airflow/dags/llm_test.py", line 299, in <module>
    check_completion >> TriggerDagRunOperator(
                        ^^^^^^^^^^^^^^^^^^^^^^
  File "/home/airflow/.local/lib/python3.12/site-packages/airflow/models/baseoperator.py", line 501, in apply_defaults
    result = func(self, **kwargs, default_args=default_args)
             ^^^^^^^^^^^^^^^^^^^^^^^^^^^^^^^^^^^^^^^^^^^^^^^
  File "/home/airflow/.local/lib/python3.12/site-packages/airflow/operators/trigger_dagrun.py", line 145, in __init__
    super().__init__(**kwargs)
  File "/home/airflow/.local/lib/python3.12/site-packages/airflow/models/baseoperator.py", line 501, in apply_defaults
    result = func(self, **kwargs, default_args=default_args)
             ^^^^^^^^^^^^^^^^^^^^^^^^^^^^^^^^^^^^^^^^^^^^^^^
  File "/home/airflow/.local/lib/python3.12/site-packages/airflow/models/baseoperator.py", line 949, in __init__
    raise AirflowException(
airflow.exceptions.AirflowException: Invalid arguments were passed to TriggerDagRunOperator (task_id: conditionally_trigger_next_run). Invalid arguments were:
**kwargs: {'python_callable': <function <lambda> at 0x7f7ca6934220>}
[2024-11-30T23:51:39.342+0000] {processor.py:927} WARNING - No viable dags retrieved from /opt/airflow/dags/llm_test.py
[2024-11-30T23:51:39.357+0000] {processor.py:208} INFO - Processing /opt/airflow/dags/llm_test.py took 0.524 seconds
[2024-11-30T23:52:09.595+0000] {processor.py:186} INFO - Started process (PID=257) to work on /opt/airflow/dags/llm_test.py
[2024-11-30T23:52:09.596+0000] {processor.py:914} INFO - Processing file /opt/airflow/dags/llm_test.py for tasks to queue
[2024-11-30T23:52:09.598+0000] {logging_mixin.py:190} INFO - [2024-11-30T23:52:09.598+0000] {dagbag.py:588} INFO - Filling up the DagBag from /opt/airflow/dags/llm_test.py
[2024-11-30T23:52:09.975+0000] {logging_mixin.py:190} INFO - [2024-11-30T23:52:09.972+0000] {dagbag.py:387} ERROR - Failed to import: /opt/airflow/dags/llm_test.py
Traceback (most recent call last):
  File "/home/airflow/.local/lib/python3.12/site-packages/airflow/models/dagbag.py", line 383, in parse
    loader.exec_module(new_module)
  File "<frozen importlib._bootstrap_external>", line 995, in exec_module
  File "<frozen importlib._bootstrap>", line 488, in _call_with_frames_removed
  File "/opt/airflow/dags/llm_test.py", line 299, in <module>
    check_completion >> TriggerDagRunOperator(
                        ^^^^^^^^^^^^^^^^^^^^^^
  File "/home/airflow/.local/lib/python3.12/site-packages/airflow/models/baseoperator.py", line 501, in apply_defaults
    result = func(self, **kwargs, default_args=default_args)
             ^^^^^^^^^^^^^^^^^^^^^^^^^^^^^^^^^^^^^^^^^^^^^^^
  File "/home/airflow/.local/lib/python3.12/site-packages/airflow/operators/trigger_dagrun.py", line 145, in __init__
    super().__init__(**kwargs)
  File "/home/airflow/.local/lib/python3.12/site-packages/airflow/models/baseoperator.py", line 501, in apply_defaults
    result = func(self, **kwargs, default_args=default_args)
             ^^^^^^^^^^^^^^^^^^^^^^^^^^^^^^^^^^^^^^^^^^^^^^^
  File "/home/airflow/.local/lib/python3.12/site-packages/airflow/models/baseoperator.py", line 949, in __init__
    raise AirflowException(
airflow.exceptions.AirflowException: Invalid arguments were passed to TriggerDagRunOperator (task_id: conditionally_trigger_next_run). Invalid arguments were:
**kwargs: {'python_callable': <function <lambda> at 0x7f7ca6934220>}
[2024-11-30T23:52:09.976+0000] {processor.py:927} WARNING - No viable dags retrieved from /opt/airflow/dags/llm_test.py
[2024-11-30T23:52:09.991+0000] {processor.py:208} INFO - Processing /opt/airflow/dags/llm_test.py took 0.400 seconds
[2024-11-30T23:52:40.317+0000] {processor.py:186} INFO - Started process (PID=275) to work on /opt/airflow/dags/llm_test.py
[2024-11-30T23:52:40.318+0000] {processor.py:914} INFO - Processing file /opt/airflow/dags/llm_test.py for tasks to queue
[2024-11-30T23:52:40.320+0000] {logging_mixin.py:190} INFO - [2024-11-30T23:52:40.319+0000] {dagbag.py:588} INFO - Filling up the DagBag from /opt/airflow/dags/llm_test.py
[2024-11-30T23:52:40.679+0000] {logging_mixin.py:190} INFO - [2024-11-30T23:52:40.675+0000] {dagbag.py:387} ERROR - Failed to import: /opt/airflow/dags/llm_test.py
Traceback (most recent call last):
  File "/home/airflow/.local/lib/python3.12/site-packages/airflow/models/dagbag.py", line 383, in parse
    loader.exec_module(new_module)
  File "<frozen importlib._bootstrap_external>", line 995, in exec_module
  File "<frozen importlib._bootstrap>", line 488, in _call_with_frames_removed
  File "/opt/airflow/dags/llm_test.py", line 299, in <module>
    check_completion >> TriggerDagRunOperator(
                        ^^^^^^^^^^^^^^^^^^^^^^
  File "/home/airflow/.local/lib/python3.12/site-packages/airflow/models/baseoperator.py", line 501, in apply_defaults
    result = func(self, **kwargs, default_args=default_args)
             ^^^^^^^^^^^^^^^^^^^^^^^^^^^^^^^^^^^^^^^^^^^^^^^
  File "/home/airflow/.local/lib/python3.12/site-packages/airflow/operators/trigger_dagrun.py", line 145, in __init__
    super().__init__(**kwargs)
  File "/home/airflow/.local/lib/python3.12/site-packages/airflow/models/baseoperator.py", line 501, in apply_defaults
    result = func(self, **kwargs, default_args=default_args)
             ^^^^^^^^^^^^^^^^^^^^^^^^^^^^^^^^^^^^^^^^^^^^^^^
  File "/home/airflow/.local/lib/python3.12/site-packages/airflow/models/baseoperator.py", line 949, in __init__
    raise AirflowException(
airflow.exceptions.AirflowException: Invalid arguments were passed to TriggerDagRunOperator (task_id: conditionally_trigger_next_run). Invalid arguments were:
**kwargs: {'python_callable': <function <lambda> at 0x7f7ca6936700>}
[2024-11-30T23:52:40.680+0000] {processor.py:927} WARNING - No viable dags retrieved from /opt/airflow/dags/llm_test.py
[2024-11-30T23:52:40.695+0000] {processor.py:208} INFO - Processing /opt/airflow/dags/llm_test.py took 0.382 seconds
[2024-11-30T23:57:15.943+0000] {processor.py:186} INFO - Started process (PID=54) to work on /opt/airflow/dags/llm_test.py
[2024-11-30T23:57:15.944+0000] {processor.py:914} INFO - Processing file /opt/airflow/dags/llm_test.py for tasks to queue
[2024-11-30T23:57:15.946+0000] {logging_mixin.py:190} INFO - [2024-11-30T23:57:15.946+0000] {dagbag.py:588} INFO - Filling up the DagBag from /opt/airflow/dags/llm_test.py
[2024-11-30T23:57:17.553+0000] {logging_mixin.py:190} INFO - [2024-11-30T23:57:17.546+0000] {dagbag.py:387} ERROR - Failed to import: /opt/airflow/dags/llm_test.py
Traceback (most recent call last):
  File "/home/airflow/.local/lib/python3.12/site-packages/airflow/models/dagbag.py", line 383, in parse
    loader.exec_module(new_module)
  File "<frozen importlib._bootstrap_external>", line 995, in exec_module
  File "<frozen importlib._bootstrap>", line 488, in _call_with_frames_removed
  File "/opt/airflow/dags/llm_test.py", line 299, in <module>
    check_completion >> TriggerDagRunOperator(
                        ^^^^^^^^^^^^^^^^^^^^^^
  File "/home/airflow/.local/lib/python3.12/site-packages/airflow/models/baseoperator.py", line 501, in apply_defaults
    result = func(self, **kwargs, default_args=default_args)
             ^^^^^^^^^^^^^^^^^^^^^^^^^^^^^^^^^^^^^^^^^^^^^^^
  File "/home/airflow/.local/lib/python3.12/site-packages/airflow/operators/trigger_dagrun.py", line 145, in __init__
    super().__init__(**kwargs)
  File "/home/airflow/.local/lib/python3.12/site-packages/airflow/models/baseoperator.py", line 501, in apply_defaults
    result = func(self, **kwargs, default_args=default_args)
             ^^^^^^^^^^^^^^^^^^^^^^^^^^^^^^^^^^^^^^^^^^^^^^^
  File "/home/airflow/.local/lib/python3.12/site-packages/airflow/models/baseoperator.py", line 949, in __init__
    raise AirflowException(
airflow.exceptions.AirflowException: Invalid arguments were passed to TriggerDagRunOperator (task_id: conditionally_trigger_next_run). Invalid arguments were:
**kwargs: {'python_callable': <function <lambda> at 0x7ff1739547c0>}
[2024-11-30T23:57:17.555+0000] {processor.py:927} WARNING - No viable dags retrieved from /opt/airflow/dags/llm_test.py
[2024-11-30T23:57:17.583+0000] {processor.py:208} INFO - Processing /opt/airflow/dags/llm_test.py took 1.646 seconds
