[2024-12-05T18:21:33.306+0000] {local_task_job_runner.py:123} INFO - ::group::Pre task execution logs
[2024-12-05T18:21:33.318+0000] {taskinstance.py:2613} INFO - Dependencies all met for dep_context=non-requeueable deps ti=<TaskInstance: ETL.load_csv_to_postgres manual__2024-12-05T18:21:29.605773+00:00 [queued]>
[2024-12-05T18:21:33.323+0000] {taskinstance.py:2613} INFO - Dependencies all met for dep_context=requeueable deps ti=<TaskInstance: ETL.load_csv_to_postgres manual__2024-12-05T18:21:29.605773+00:00 [queued]>
[2024-12-05T18:21:33.324+0000] {taskinstance.py:2866} INFO - Starting attempt 1 of 1
[2024-12-05T18:21:33.333+0000] {taskinstance.py:2889} INFO - Executing <Task(PythonOperator): load_csv_to_postgres> on 2024-12-05 18:21:29.605773+00:00
[2024-12-05T18:21:33.339+0000] {warnings.py:112} WARNING - /home/***/.local/lib/python3.12/site-packages/***/task/task_runner/standard_task_runner.py:70: DeprecationWarning: This process (pid=843) is multi-threaded, use of fork() may lead to deadlocks in the child.
  pid = os.fork()

[2024-12-05T18:21:33.341+0000] {standard_task_runner.py:72} INFO - Started process 845 to run task
[2024-12-05T18:21:33.341+0000] {standard_task_runner.py:104} INFO - Running: ['***', 'tasks', 'run', 'ETL', 'load_csv_to_postgres', 'manual__2024-12-05T18:21:29.605773+00:00', '--job-id', '377', '--raw', '--subdir', 'DAGS_FOLDER/etl.py', '--cfg-path', '/tmp/tmpz4tbuj8b']
[2024-12-05T18:21:33.342+0000] {standard_task_runner.py:105} INFO - Job 377: Subtask load_csv_to_postgres
[2024-12-05T18:21:33.372+0000] {task_command.py:467} INFO - Running <TaskInstance: ETL.load_csv_to_postgres manual__2024-12-05T18:21:29.605773+00:00 [running]> on host 886abab866d2
[2024-12-05T18:21:33.550+0000] {taskinstance.py:3132} INFO - Exporting env vars: AIRFLOW_CTX_DAG_OWNER='artzsh' AIRFLOW_CTX_DAG_ID='ETL' AIRFLOW_CTX_TASK_ID='load_csv_to_postgres' AIRFLOW_CTX_EXECUTION_DATE='2024-12-05T18:21:29.605773+00:00' AIRFLOW_CTX_TRY_NUMBER='1' AIRFLOW_CTX_DAG_RUN_ID='manual__2024-12-05T18:21:29.605773+00:00'
[2024-12-05T18:21:33.551+0000] {taskinstance.py:731} INFO - ::endgroup::
[2024-12-05T18:21:33.571+0000] {etl.py:52} INFO - Обрабатываем ключ: 8
[2024-12-05T18:21:33.571+0000] {etl.py:53} INFO - Информация о таблице: {'1': {'dataset_url': 'https://data.rees46.com/datasets/marketplace/2019-Oct.csv.gz', 'table_name': 'eCommerce_Oct', 'brands_table_name': 'brands_Oct', 'categories_table_name': 'categories_Oct'}, '2': {'dataset_url': 'https://data.rees46.com/datasets/marketplace/2019-Nov.csv.gz', 'table_name': 'eCommerce_Nov', 'brands_table_name': 'brands_Nov', 'categories_table_name': 'categories_Nov'}, '3': {'dataset_url': 'https://data.rees46.com/datasets/marketplace/2019-Dec.csv.gz', 'table_name': 'eCommerce_Dec', 'brands_table_name': 'brands_Dec', 'categories_table_name': 'categories_Dec'}, '4': {'dataset_url': 'https://data.rees46.com/datasets/marketplace/2020-Jan.csv.gz', 'table_name': 'eCommerce_Jan', 'brands_table_name': 'brands_Jan', 'categories_table_name': 'categories_Jan'}, '5': {'dataset_url': 'https://data.rees46.com/datasets/marketplace/2020-Feb.csv.gz', 'table_name': 'eCommerce_Feb', 'brands_table_name': 'brands_Feb', 'categories_table_name': 'categories_Feb'}, '6': {'dataset_url': 'https://data.rees46.com/datasets/marketplace/2020-Mar.csv.gz', 'table_name': 'eCommerce_Mar', 'brands_table_name': 'brands_Mar', 'categories_table_name': 'categories_Mar'}, '7': {'dataset_url': 'https://data.rees46.com/datasets/marketplace/2020-Apr.csv.gz', 'table_name': 'eCommerce_Apr', 'brands_table_name': 'brands_Apr', 'categories_table_name': 'categories_Apr'}}
[2024-12-05T18:21:33.571+0000] {taskinstance.py:3311} ERROR - Task failed with exception
Traceback (most recent call last):
  File "/home/airflow/.local/lib/python3.12/site-packages/airflow/models/taskinstance.py", line 767, in _execute_task
    result = _execute_callable(context=context, **execute_callable_kwargs)
             ^^^^^^^^^^^^^^^^^^^^^^^^^^^^^^^^^^^^^^^^^^^^^^^^^^^^^^^^^^^^^
  File "/home/airflow/.local/lib/python3.12/site-packages/airflow/models/taskinstance.py", line 733, in _execute_callable
    return ExecutionCallableRunner(
           ^^^^^^^^^^^^^^^^^^^^^^^^
  File "/home/airflow/.local/lib/python3.12/site-packages/airflow/utils/operator_helpers.py", line 252, in run
    return self.func(*args, **kwargs)
           ^^^^^^^^^^^^^^^^^^^^^^^^^^
  File "/home/airflow/.local/lib/python3.12/site-packages/airflow/models/baseoperator.py", line 417, in wrapper
    return func(self, *args, **kwargs)
           ^^^^^^^^^^^^^^^^^^^^^^^^^^^
  File "/home/airflow/.local/lib/python3.12/site-packages/airflow/operators/python.py", line 238, in execute
    return_value = self.execute_callable()
                   ^^^^^^^^^^^^^^^^^^^^^^^
  File "/home/airflow/.local/lib/python3.12/site-packages/airflow/operators/python.py", line 256, in execute_callable
    return runner.run(*self.op_args, **self.op_kwargs)
           ^^^^^^^^^^^^^^^^^^^^^^^^^^^^^^^^^^^^^^^^^^^
  File "/home/airflow/.local/lib/python3.12/site-packages/airflow/utils/operator_helpers.py", line 252, in run
    return self.func(*args, **kwargs)
           ^^^^^^^^^^^^^^^^^^^^^^^^^^
  File "/opt/airflow/dags/etl.py", line 58, in load_csv_to_postgres
    raise ValueError(f"Ключ '{key_str}' не найден в tables_json.")
ValueError: Ключ '8' не найден в tables_json.
[2024-12-05T18:21:33.578+0000] {taskinstance.py:1225} INFO - Marking task as FAILED. dag_id=ETL, task_id=load_csv_to_postgres, run_id=manual__2024-12-05T18:21:29.605773+00:00, execution_date=20241205T182129, start_date=20241205T182133, end_date=20241205T182133
[2024-12-05T18:21:33.587+0000] {taskinstance.py:340} INFO - ::group::Post task execution logs
[2024-12-05T18:21:33.588+0000] {standard_task_runner.py:124} ERROR - Failed to execute job 377 for task load_csv_to_postgres (Ключ '8' не найден в tables_json.; 845)
Traceback (most recent call last):
  File "/home/airflow/.local/lib/python3.12/site-packages/airflow/task/task_runner/standard_task_runner.py", line 117, in _start_by_fork
    ret = args.func(args, dag=self.dag)
          ^^^^^^^^^^^^^^^^^^^^^^^^^^^^^
  File "/home/airflow/.local/lib/python3.12/site-packages/airflow/cli/cli_config.py", line 49, in command
    return func(*args, **kwargs)
           ^^^^^^^^^^^^^^^^^^^^^
  File "/home/airflow/.local/lib/python3.12/site-packages/airflow/utils/cli.py", line 116, in wrapper
    return f(*args, **kwargs)
           ^^^^^^^^^^^^^^^^^^
  File "/home/airflow/.local/lib/python3.12/site-packages/airflow/cli/commands/task_command.py", line 483, in task_run
    task_return_code = _run_task_by_selected_method(args, _dag, ti)
                       ^^^^^^^^^^^^^^^^^^^^^^^^^^^^^^^^^^^^^^^^^^^^
  File "/home/airflow/.local/lib/python3.12/site-packages/airflow/cli/commands/task_command.py", line 256, in _run_task_by_selected_method
    return _run_raw_task(args, ti)
           ^^^^^^^^^^^^^^^^^^^^^^^
  File "/home/airflow/.local/lib/python3.12/site-packages/airflow/cli/commands/task_command.py", line 341, in _run_raw_task
    return ti._run_raw_task(
           ^^^^^^^^^^^^^^^^^
  File "/home/airflow/.local/lib/python3.12/site-packages/airflow/utils/session.py", line 97, in wrapper
    return func(*args, session=session, **kwargs)
           ^^^^^^^^^^^^^^^^^^^^^^^^^^^^^^^^^^^^^^
  File "/home/airflow/.local/lib/python3.12/site-packages/airflow/models/taskinstance.py", line 3005, in _run_raw_task
    return _run_raw_task(
           ^^^^^^^^^^^^^^
  File "/home/airflow/.local/lib/python3.12/site-packages/airflow/models/taskinstance.py", line 273, in _run_raw_task
    TaskInstance._execute_task_with_callbacks(
  File "/home/airflow/.local/lib/python3.12/site-packages/airflow/models/taskinstance.py", line 3159, in _execute_task_with_callbacks
    result = self._execute_task(context, task_orig)
             ^^^^^^^^^^^^^^^^^^^^^^^^^^^^^^^^^^^^^^
  File "/home/airflow/.local/lib/python3.12/site-packages/airflow/models/taskinstance.py", line 3183, in _execute_task
    return _execute_task(self, context, task_orig)
           ^^^^^^^^^^^^^^^^^^^^^^^^^^^^^^^^^^^^^^^
  File "/home/airflow/.local/lib/python3.12/site-packages/airflow/models/taskinstance.py", line 767, in _execute_task
    result = _execute_callable(context=context, **execute_callable_kwargs)
             ^^^^^^^^^^^^^^^^^^^^^^^^^^^^^^^^^^^^^^^^^^^^^^^^^^^^^^^^^^^^^
  File "/home/airflow/.local/lib/python3.12/site-packages/airflow/models/taskinstance.py", line 733, in _execute_callable
    return ExecutionCallableRunner(
           ^^^^^^^^^^^^^^^^^^^^^^^^
  File "/home/airflow/.local/lib/python3.12/site-packages/airflow/utils/operator_helpers.py", line 252, in run
    return self.func(*args, **kwargs)
           ^^^^^^^^^^^^^^^^^^^^^^^^^^
  File "/home/airflow/.local/lib/python3.12/site-packages/airflow/models/baseoperator.py", line 417, in wrapper
    return func(self, *args, **kwargs)
           ^^^^^^^^^^^^^^^^^^^^^^^^^^^
  File "/home/airflow/.local/lib/python3.12/site-packages/airflow/operators/python.py", line 238, in execute
    return_value = self.execute_callable()
                   ^^^^^^^^^^^^^^^^^^^^^^^
  File "/home/airflow/.local/lib/python3.12/site-packages/airflow/operators/python.py", line 256, in execute_callable
    return runner.run(*self.op_args, **self.op_kwargs)
           ^^^^^^^^^^^^^^^^^^^^^^^^^^^^^^^^^^^^^^^^^^^
  File "/home/airflow/.local/lib/python3.12/site-packages/airflow/utils/operator_helpers.py", line 252, in run
    return self.func(*args, **kwargs)
           ^^^^^^^^^^^^^^^^^^^^^^^^^^
  File "/opt/airflow/dags/etl.py", line 58, in load_csv_to_postgres
    raise ValueError(f"Ключ '{key_str}' не найден в tables_json.")
ValueError: Ключ '8' не найден в tables_json.
[2024-12-05T18:21:33.635+0000] {local_task_job_runner.py:266} INFO - Task exited with return code 1
[2024-12-05T18:21:33.648+0000] {taskinstance.py:3895} INFO - 0 downstream tasks scheduled from follow-on schedule check
[2024-12-05T18:21:33.652+0000] {local_task_job_runner.py:245} INFO - ::endgroup::
